Workbook
Name \c: #N/A
Name \g: #N/A
Name \o: #N/A
Name \p: #N/A
Name Aansluiting: [1]Blad3!$B$8:$B$12
Name Afdrukbereik_MI: #REF!
Name Afdrukgebied: #REF!
Name arm: [1]Blad3!$B$15:$B$17
Name Cutters: [2]Codes!$U$3:$U$15
Name Dagen: #REF!
Name deellijnnummer: '[2] Overzicht deellijn'!$D$7:$D$104
Name diam: [2]Codes!$B$2:$B$44
Name diameters: '[2]Gewicht kous'!$A$4:$A$26
Name diktes: '[2]Gewicht kous'!$B$3:$AD$3
Name eindv: #REF!
Name even: [1]Blad1!#REF!
Name harstotaal: [2]Menggegevens!$A$3:$C$11
Name IDcode: [2]Voorbereiding!$D$9:$D$209
Name Impreg: #REF!
Name Inbrengen: [2]Codes!$Y$2:$Y$12
Name indicatie: #REF!
Name INSITUFORM: #N/A
Name inversiediepte: [2]Codes!$Y$2:$AB$12
Name inversiehoogte: [2]Codes!$AL$3:$AM$2017
Name KOLOM: '[2] Overzicht'!$C$315
Name kousdikte: [2]Codes!$AI$2:$AI$28
Name kousdiktes: [2]Codes!$AI$2:$AJ$28
Name kousdiktes\: [2]Codes!$CF$3:$CG$177
Name lengteberekening: [2]Codes!$AO$3:$AP$607
Name mat: #REF!
Name menghars: [2]Menggegevens!$A$3:$A$10
Name Nachtwerk: #REF!
Name Namen: [1]Lijsten!$B$12:$B$29
Name operator: [3]Lijsten!$C$4:$C$13
Name operator_ass: [3]Lijsten!$D$4:$D$13
Name Ploeg: #REF!
Name ploegen: [2]Codes!$BP$3:$BP$15
Name PUT: #REF!
Name putnr: #REF!
Name putnummer: #REF!
Name re: #REF!
Name RIJ: '[2] Overzicht'!$C$314
Name Saertex_S: Prijzen!$B$14:$S$70
Name slijptol: [1]Blad3!$B$13:$B$14
Name Soort_inlaat: [3]Lijsten!$H$4:$H$13
Name TVK: [3]Lijsten!$G$4:$G$13
Name uitv: #REF!
Name uitvoerders: [2]Codes!$Q$2:$Q$12
Name VALILIST: #REF!
Name Wagennummers: [1]Lijsten!$B$3:$B$10
Name Wakers: #REF!
Name Werkzaamheden: #REF!

Sheet Overzicht
B2: KOSTEN- & RESULTAATOVERZICHT
B3: Alle kosten in één oogopslag — gekoppeld aan de tabbladen Calculatie, Prijzen en Insituform-calc.
B5: Project | D5: =Calculatie!B3
B6: Opdrachtgever | D6: =Calculatie!B4
B7: Projectnummer | D7: =Calculatie!B2
B9: OPBRENGSTEN
B10: Gecorrigeerde aanneemsom | D10: =Calculatie!F24
B11: Totaal gefactureerd | D11: =Calculatie!F33
B12: Nog te factureren | D12: =Calculatie!F35
B14: KOSTEN
B15: Geboekte kosten t/m periode | D15: =Calculatie!F40
B16: Nog te boeken kosten | D16: =Calculatie!F51
B17: Prognose nog uit te voeren | D17: =Calculatie!F224
B18: Totaal prognose kosten einde werk | D18: =Calculatie!F227
B20: PROGNOSE RESULTAAT EINDE WERK
B21: Opbrengsten | D21: =Calculatie!F232
B22: Kosten | D22: =Calculatie!F233
B23: RESULTAAT | D23: =Calculatie!F235
B25: INSITUFORM DETAILCALCULATIE (aanvullend)
B26: Totaal materiaal (impregnatie+droog+sundry) | D26: ='Insituform-calc'!$T$75
B28: INDEXPERCENTAGES
B29: M-/S+ liner (Prijzen!AL11) | D29: =Prijzen!AL11
B30: Insituform (Prijzen!AL72) | D30: =Prijzen!AL72

Sheet Periodetrend
A1: PERIODETREND — materiaalkosten verdeeld over periodes (4 weken) o.b.v. inbrengdatum
A2: Periode 1 startdatum invullen (geel); de overige start/einddatums rekenen door per 28 dagen. Kousen vallen automatisch in de juiste periode.
A4: Periode | B4: Startdatum | C4: Einddatum | D4: Materiaal in periode | E4: Materiaal gerealiseerd t/m periode | F4: Materiaal nog te verwachten | G4: Periodeblad (tabnaam) | H4: Prognoseresultaat einde werk
A5: Periode 1 | B5: 45292 | C5: =B5+27 | D5: =SUMIFS(Kousen!$I$5:$I$80,Kousen!$H$5:$H$80,">="&$B5,Kousen!$H$5:$H$80,"<="&$C5) | E5: =SUMIFS(Kousen!$I$5:$I$80,Kousen!$H$5:$H$80,"<="&$C5) | F5: =SUM(Kousen!$I$5:$I$80)-$E5 | H5: =IFERROR(INDIRECT("'"&$G5&"'!F235"),"")
A6: Periode 2 | B6: =C5+1 | C6: =B6+27 | D6: =SUMIFS(Kousen!$I$5:$I$80,Kousen!$H$5:$H$80,">="&$B6,Kousen!$H$5:$H$80,"<="&$C6) | E6: =SUMIFS(Kousen!$I$5:$I$80,Kousen!$H$5:$H$80,"<="&$C6) | F6: =SUM(Kousen!$I$5:$I$80)-$E6 | H6: =IFERROR(INDIRECT("'"&$G6&"'!F235"),"")
A7: Periode 3 | B7: =C6+1 | C7: =B7+27 | D7: =SUMIFS(Kousen!$I$5:$I$80,Kousen!$H$5:$H$80,">="&$B7,Kousen!$H$5:$H$80,"<="&$C7) | E7: =SUMIFS(Kousen!$I$5:$I$80,Kousen!$H$5:$H$80,"<="&$C7) | F7: =SUM(Kousen!$I$5:$I$80)-$E7 | H7: =IFERROR(INDIRECT("'"&$G7&"'!F235"),"")
A8: Periode 4 | B8: =C7+1 | C8: =B8+27 | D8: =SUMIFS(Kousen!$I$5:$I$80,Kousen!$H$5:$H$80,">="&$B8,Kousen!$H$5:$H$80,"<="&$C8) | E8: =SUMIFS(Kousen!$I$5:$I$80,Kousen!$H$5:$H$80,"<="&$C8) | F8: =SUM(Kousen!$I$5:$I$80)-$E8 | H8: =IFERROR(INDIRECT("'"&$G8&"'!F235"),"")
A9: Periode 5 | B9: =C8+1 | C9: =B9+27 | D9: =SUMIFS(Kousen!$I$5:$I$80,Kousen!$H$5:$H$80,">="&$B9,Kousen!$H$5:$H$80,"<="&$C9) | E9: =SUMIFS(Kousen!$I$5:$I$80,Kousen!$H$5:$H$80,"<="&$C9) | F9: =SUM(Kousen!$I$5:$I$80)-$E9 | H9: =IFERROR(INDIRECT("'"&$G9&"'!F235"),"")
A10: Periode 6 | B10: =C9+1 | C10: =B10+27 | D10: =SUMIFS(Kousen!$I$5:$I$80,Kousen!$H$5:$H$80,">="&$B10,Kousen!$H$5:$H$80,"<="&$C10) | E10: =SUMIFS(Kousen!$I$5:$I$80,Kousen!$H$5:$H$80,"<="&$C10) | F10: =SUM(Kousen!$I$5:$I$80)-$E10 | H10: =IFERROR(INDIRECT("'"&$G10&"'!F235"),"")
A11: Periode 7 | B11: =C10+1 | C11: =B11+27 | D11: =SUMIFS(Kousen!$I$5:$I$80,Kousen!$H$5:$H$80,">="&$B11,Kousen!$H$5:$H$80,"<="&$C11) | E11: =SUMIFS(Kousen!$I$5:$I$80,Kousen!$H$5:$H$80,"<="&$C11) | F11: =SUM(Kousen!$I$5:$I$80)-$E11 | H11: =IFERROR(INDIRECT("'"&$G11&"'!F235"),"")
A12: Periode 8 | B12: =C11+1 | C12: =B12+27 | D12: =SUMIFS(Kousen!$I$5:$I$80,Kousen!$H$5:$H$80,">="&$B12,Kousen!$H$5:$H$80,"<="&$C12) | E12: =SUMIFS(Kousen!$I$5:$I$80,Kousen!$H$5:$H$80,"<="&$C12) | F12: =SUM(Kousen!$I$5:$I$80)-$E12 | H12: =IFERROR(INDIRECT("'"&$G12&"'!F235"),"")
A13: Periode 9 | B13: =C12+1 | C13: =B13+27 | D13: =SUMIFS(Kousen!$I$5:$I$80,Kousen!$H$5:$H$80,">="&$B13,Kousen!$H$5:$H$80,"<="&$C13) | E13: =SUMIFS(Kousen!$I$5:$I$80,Kousen!$H$5:$H$80,"<="&$C13) | F13: =SUM(Kousen!$I$5:$I$80)-$E13 | H13: =IFERROR(INDIRECT("'"&$G13&"'!F235"),"")
A14: Periode 10 | B14: =C13+1 | C14: =B14+27 | D14: =SUMIFS(Kousen!$I$5:$I$80,Kousen!$H$5:$H$80,">="&$B14,Kousen!$H$5:$H$80,"<="&$C14) | E14: =SUMIFS(Kousen!$I$5:$I$80,Kousen!$H$5:$H$80,"<="&$C14) | F14: =SUM(Kousen!$I$5:$I$80)-$E14 | H14: =IFERROR(INDIRECT("'"&$G14&"'!F235"),"")
A15: Periode 11 | B15: =C14+1 | C15: =B15+27 | D15: =SUMIFS(Kousen!$I$5:$I$80,Kousen!$H$5:$H$80,">="&$B15,Kousen!$H$5:$H$80,"<="&$C15) | E15: =SUMIFS(Kousen!$I$5:$I$80,Kousen!$H$5:$H$80,"<="&$C15) | F15: =SUM(Kousen!$I$5:$I$80)-$E15 | H15: =IFERROR(INDIRECT("'"&$G15&"'!F235"),"")
A16: Periode 12 | B16: =C15+1 | C16: =B16+27 | D16: =SUMIFS(Kousen!$I$5:$I$80,Kousen!$H$5:$H$80,">="&$B16,Kousen!$H$5:$H$80,"<="&$C16) | E16: =SUMIFS(Kousen!$I$5:$I$80,Kousen!$H$5:$H$80,"<="&$C16) | F16: =SUM(Kousen!$I$5:$I$80)-$E16 | H16: =IFERROR(INDIRECT("'"&$G16&"'!F235"),"")
A17: Periode 13 | B17: =C16+1 | C17: =B17+27 | D17: =SUMIFS(Kousen!$I$5:$I$80,Kousen!$H$5:$H$80,">="&$B17,Kousen!$H$5:$H$80,"<="&$C17) | E17: =SUMIFS(Kousen!$I$5:$I$80,Kousen!$H$5:$H$80,"<="&$C17) | F17: =SUM(Kousen!$I$5:$I$80)-$E17 | H17: =IFERROR(INDIRECT("'"&$G17&"'!F235"),"")
A19: Totaal materiaal alle kousen: | D19: =SUM(Kousen!$I$5:$I$80)

Sheet Kousen
A1: KOUSEN — masterlijst met inbrengdatum (bepaalt de periode) en automatische kostprijs
A2: Geel = invoer. Kostprijs en periode rekenen automatisch (kostprijs via Prijzen-blad: UV = liner×0,58, JK = Insituform/m).
A4: Kousnr | B4: Locatie / straat | C4: Type | D4: Liner-soort | E4: DN | F4: Dikte (mm) | G4: Lengte (m) | H4: Inbreng- datum | I4: Kostprijs (€) | J4: Periode (auto)
A5: 501 | B5: schansbaan | C5: JK | E5: 250 | F5: 6 | G5: 121.8 | H5: 45294 | I5: =IFERROR(IF($C5="UV",IF($D5="S+ liner",$G5*INDEX(Prijzen!$C$15:$P$70,MATCH($E5,Prijzen!$B$15:$B$70,0),MATCH($F5,Prijzen!$C$14:$O$14,0))*0.58,IF($D5="M liner",$G5*INDEX(Prijzen!$C$2:$P$11,MATCH($E5,Prijzen!$B$2:$B$11,0),MATCH($F5,Prijzen!$C$1:$P$1,0))*0.58,0)),$G5*INDEX(Prijzen!$C$73:$P$94,MATCH($E5,Prijzen!$B$73:$B$94,0),MATCH($F5,Prijzen!$C$72:$P$72,0))),0) | J5: =IF($H5="","nog te plannen",IFERROR(LOOKUP($H5,Periodetrend!$B$5:$B$17,Periodetrend!$A$5:$A$17),"vóór P1"))
A6: 502 | B6: semsschans | C6: JK | E6: 250 | F6: 6 | G6: 30.6 | H6: 45296 | I6: =IFERROR(IF($C6="UV",IF($D6="S+ liner",$G6*INDEX(Prijzen!$C$15:$P$70,MATCH($E6,Prijzen!$B$15:$B$70,0),MATCH($F6,Prijzen!$C$14:$O$14,0))*0.58,IF($D6="M liner",$G6*INDEX(Prijzen!$C$2:$P$11,MATCH($E6,Prijzen!$B$2:$B$11,0),MATCH($F6,Prijzen!$C$1:$P$1,0))*0.58,0)),$G6*INDEX(Prijzen!$C$73:$P$94,MATCH($E6,Prijzen!$B$73:$B$94,0),MATCH($F6,Prijzen!$C$72:$P$72,0))),0) | J6: =IF($H6="","nog te plannen",IFERROR(LOOKUP($H6,Periodetrend!$B$5:$B$17,Periodetrend!$A$5:$A$17),"vóór P1"))
A7: 503 | B7: semsschans | C7: JK | E7: 250 | F7: 6 | G7: 60 | H7: 45298 | I7: =IFERROR(IF($C7="UV",IF($D7="S+ liner",$G7*INDEX(Prijzen!$C$15:$P$70,MATCH($E7,Prijzen!$B$15:$B$70,0),MATCH($F7,Prijzen!$C$14:$O$14,0))*0.58,IF($D7="M liner",$G7*INDEX(Prijzen!$C$2:$P$11,MATCH($E7,Prijzen!$B$2:$B$11,0),MATCH($F7,Prijzen!$C$1:$P$1,0))*0.58,0)),$G7*INDEX(Prijzen!$C$73:$P$94,MATCH($E7,Prijzen!$B$73:$B$94,0),MATCH($F7,Prijzen!$C$72:$P$72,0))),0) | J7: =IF($H7="","nog te plannen",IFERROR(LOOKUP($H7,Periodetrend!$B$5:$B$17,Periodetrend!$A$5:$A$17),"vóór P1"))
A8: 504 | B8: van rijswijckschans | C8: JK | E8: 250 | F8: 6 | G8: 104.7 | H8: 45300 | I8: =IFERROR(IF($C8="UV",IF($D8="S+ liner",$G8*INDEX(Prijzen!$C$15:$P$70,MATCH($E8,Prijzen!$B$15:$B$70,0),MATCH($F8,Prijzen!$C$14:$O$14,0))*0.58,IF($D8="M liner",$G8*INDEX(Prijzen!$C$2:$P$11,MATCH($E8,Prijzen!$B$2:$B$11,0),MATCH($F8,Prijzen!$C$1:$P$1,0))*0.58,0)),$G8*INDEX(Prijzen!$C$73:$P$94,MATCH($E8,Prijzen!$B$73:$B$94,0),MATCH($F8,Prijzen!$C$72:$P$72,0))),0) | J8: =IF($H8="","nog te plannen",IFERROR(LOOKUP($H8,Periodetrend!$B$5:$B$17,Periodetrend!$A$5:$A$17),"vóór P1"))
A9: 505 | B9: van rijswijckschans | C9: JK | E9: 250 | F9: 6 | G9: 67.3 | H9: 45302 | I9: =IFERROR(IF($C9="UV",IF($D9="S+ liner",$G9*INDEX(Prijzen!$C$15:$P$70,MATCH($E9,Prijzen!$B$15:$B$70,0),MATCH($F9,Prijzen!$C$14:$O$14,0))*0.58,IF($D9="M liner",$G9*INDEX(Prijzen!$C$2:$P$11,MATCH($E9,Prijzen!$B$2:$B$11,0),MATCH($F9,Prijzen!$C$1:$P$1,0))*0.58,0)),$G9*INDEX(Prijzen!$C$73:$P$94,MATCH($E9,Prijzen!$B$73:$B$94,0),MATCH($F9,Prijzen!$C$72:$P$72,0))),0) | J9: =IF($H9="","nog te plannen",IFERROR(LOOKUP($H9,Periodetrend!$B$5:$B$17,Periodetrend!$A$5:$A$17),"vóór P1"))
A10: 506 | B10: van rijswijckschans | C10: JK | E10: 250 | F10: 6 | G10: 42.1 | H10: 45304 | I10: =IFERROR(IF($C10="UV",IF($D10="S+ liner",$G10*INDEX(Prijzen!$C$15:$P$70,MATCH($E10,Prijzen!$B$15:$B$70,0),MATCH($F10,Prijzen!$C$14:$O$14,0))*0.58,IF($D10="M liner",$G10*INDEX(Prijzen!$C$2:$P$11,MATCH($E10,Prijzen!$B$2:$B$11,0),MATCH($F10,Prijzen!$C$1:$P$1,0))*0.58,0)),$G10*INDEX(Prijzen!$C$73:$P$94,MATCH($E10,Prijzen!$B$73:$B$94,0),MATCH($F10,Prijzen!$C$72:$P$72,0))),0) | J10: =IF($H10="","nog te plannen",IFERROR(LOOKUP($H10,Periodetrend!$B$5:$B$17,Periodetrend!$A$5:$A$17),"vóór P1"))
A11: 507 | B11: van rijswijckschans | C11: JK | E11: 250 | F11: 6 | G11: 35.4 | H11: 45306 | I11: =IFERROR(IF($C11="UV",IF($D11="S+ liner",$G11*INDEX(Prijzen!$C$15:$P$70,MATCH($E11,Prijzen!$B$15:$B$70,0),MATCH($F11,Prijzen!$C$14:$O$14,0))*0.58,IF($D11="M liner",$G11*INDEX(Prijzen!$C$2:$P$11,MATCH($E11,Prijzen!$B$2:$B$11,0),MATCH($F11,Prijzen!$C$1:$P$1,0))*0.58,0)),$G11*INDEX(Prijzen!$C$73:$P$94,MATCH($E11,Prijzen!$B$73:$B$94,0),MATCH($F11,Prijzen!$C$72:$P$72,0))),0) | J11: =IF($H11="","nog te plannen",IFERROR(LOOKUP($H11,Periodetrend!$B$5:$B$17,Periodetrend!$A$5:$A$17),"vóór P1"))
A12: 508 | B12: offerhausschans | C12: JK | E12: 250 | F12: 6 | G12: 41.1 | H12: 45308 | I12: =IFERROR(IF($C12="UV",IF($D12="S+ liner",$G12*INDEX(Prijzen!$C$15:$P$70,MATCH($E12,Prijzen!$B$15:$B$70,0),MATCH($F12,Prijzen!$C$14:$O$14,0))*0.58,IF($D12="M liner",$G12*INDEX(Prijzen!$C$2:$P$11,MATCH($E12,Prijzen!$B$2:$B$11,0),MATCH($F12,Prijzen!$C$1:$P$1,0))*0.58,0)),$G12*INDEX(Prijzen!$C$73:$P$94,MATCH($E12,Prijzen!$B$73:$B$94,0),MATCH($F12,Prijzen!$C$72:$P$72,0))),0) | J12: =IF($H12="","nog te plannen",IFERROR(LOOKUP($H12,Periodetrend!$B$5:$B$17,Periodetrend!$A$5:$A$17),"vóór P1"))
A13: 509 | B13: pelschans | C13: JK | E13: 250 | F13: 6 | G13: 90.4 | H13: 45310 | I13: =IFERROR(IF($C13="UV",IF($D13="S+ liner",$G13*INDEX(Prijzen!$C$15:$P$70,MATCH($E13,Prijzen!$B$15:$B$70,0),MATCH($F13,Prijzen!$C$14:$O$14,0))*0.58,IF($D13="M liner",$G13*INDEX(Prijzen!$C$2:$P$11,MATCH($E13,Prijzen!$B$2:$B$11,0),MATCH($F13,Prijzen!$C$1:$P$1,0))*0.58,0)),$G13*INDEX(Prijzen!$C$73:$P$94,MATCH($E13,Prijzen!$B$73:$B$94,0),MATCH($F13,Prijzen!$C$72:$P$72,0))),0) | J13: =IF($H13="","nog te plannen",IFERROR(LOOKUP($H13,Periodetrend!$B$5:$B$17,Periodetrend!$A$5:$A$17),"vóór P1"))
A14: 510 | B14: merkesschans | C14: JK | E14: 250 | F14: 6 | G14: 133.9 | H14: 45321 | I14: =IFERROR(IF($C14="UV",IF($D14="S+ liner",$G14*INDEX(Prijzen!$C$15:$P$70,MATCH($E14,Prijzen!$B$15:$B$70,0),MATCH($F14,Prijzen!$C$14:$O$14,0))*0.58,IF($D14="M liner",$G14*INDEX(Prijzen!$C$2:$P$11,MATCH($E14,Prijzen!$B$2:$B$11,0),MATCH($F14,Prijzen!$C$1:$P$1,0))*0.58,0)),$G14*INDEX(Prijzen!$C$73:$P$94,MATCH($E14,Prijzen!$B$73:$B$94,0),MATCH($F14,Prijzen!$C$72:$P$72,0))),0) | J14: =IF($H14="","nog te plannen",IFERROR(LOOKUP($H14,Periodetrend!$B$5:$B$17,Periodetrend!$A$5:$A$17),"vóór P1"))
A15: 511 | B15: klinckaertschans | C15: JK | E15: 250 | F15: 6 | G15: 92.3 | H15: 45324 | I15: =IFERROR(IF($C15="UV",IF($D15="S+ liner",$G15*INDEX(Prijzen!$C$15:$P$70,MATCH($E15,Prijzen!$B$15:$B$70,0),MATCH($F15,Prijzen!$C$14:$O$14,0))*0.58,IF($D15="M liner",$G15*INDEX(Prijzen!$C$2:$P$11,MATCH($E15,Prijzen!$B$2:$B$11,0),MATCH($F15,Prijzen!$C$1:$P$1,0))*0.58,0)),$G15*INDEX(Prijzen!$C$73:$P$94,MATCH($E15,Prijzen!$B$73:$B$94,0),MATCH($F15,Prijzen!$C$72:$P$72,0))),0) | J15: =IF($H15="","nog te plannen",IFERROR(LOOKUP($H15,Periodetrend!$B$5:$B$17,Periodetrend!$A$5:$A$17),"vóór P1"))
A16: 512 | B16: lijnbaan | C16: JK | E16: 250 | F16: 6 | G16: 124.6 | H16: 45327 | I16: =IFERROR(IF($C16="UV",IF($D16="S+ liner",$G16*INDEX(Prijzen!$C$15:$P$70,MATCH($E16,Prijzen!$B$15:$B$70,0),MATCH($F16,Prijzen!$C$14:$O$14,0))*0.58,IF($D16="M liner",$G16*INDEX(Prijzen!$C$2:$P$11,MATCH($E16,Prijzen!$B$2:$B$11,0),MATCH($F16,Prijzen!$C$1:$P$1,0))*0.58,0)),$G16*INDEX(Prijzen!$C$73:$P$94,MATCH($E16,Prijzen!$B$73:$B$94,0),MATCH($F16,Prijzen!$C$72:$P$72,0))),0) | J16: =IF($H16="","nog te plannen",IFERROR(LOOKUP($H16,Periodetrend!$B$5:$B$17,Periodetrend!$A$5:$A$17),"vóór P1"))
... A29: 525 | B29: van rijswijckschans | C29: JK | E29: 250 | F29: 6 | G29: 106.1 | H29: 45370 | I29: =IFERROR(IF($C29="UV",IF($D29="S+ liner",$G29*INDEX(Prijzen!$C$15:$P$70,MATCH($E29,Prijzen!$B$15:$B$70,0),MATCH($F29,Prijzen!$C$14:$O$14,0))*0.58,IF($D29="M liner",$G29*INDEX(Prijzen!$C$2:$P$11,MATCH($E29,Prijzen!$B$2:$B$11,0),MATCH($F29,Prijzen!$C$1:$P$1,0))*0.58,0)),$G29*INDEX(Prijzen!$C$73:$P$94,MATCH($E29,Prijzen!$B$73:$B$94,0),MATCH($F29,Prijzen!$C$72:$P$72,0))),0) | J29: =IF($H29="","nog te plannen",IFERROR(LOOKUP($H29,Periodetrend!$B$5:$B$17,Periodetrend!$A$5:$A$17),"vóór P1"))
I30: =IFERROR(IF($C30="UV",IF($D30="S+ liner",$G30*INDEX(Prijzen!$C$15:$P$70,MATCH($E30,Prijzen!$B$15:$B$70,0),MATCH($F30,Prijzen!$C$14:$O$14,0))*0.58,IF($D30="M liner",$G30*INDEX(Prijzen!$C$2:$P$11,MATCH($E30,Prijzen!$B$2:$B$11,0),MATCH($F30,Prijzen!$C$1:$P$1,0))*0.58,0)),$G30*INDEX(Prijzen!$C$73:$P$94,MATCH($E30,Prijzen!$B$73:$B$94,0),MATCH($F30,Prijzen!$C$72:$P$72,0))),0) | J30: =IF($H30="","nog te plannen",IFERROR(LOOKUP($H30,Periodetrend!$B$5:$B$17,Periodetrend!$A$5:$A$17),"vóór P1"))
I31: =IFERROR(IF($C31="UV",IF($D31="S+ liner",$G31*INDEX(Prijzen!$C$15:$P$70,MATCH($E31,Prijzen!$B$15:$B$70,0),MATCH($F31,Prijzen!$C$14:$O$14,0))*0.58,IF($D31="M liner",$G31*INDEX(Prijzen!$C$2:$P$11,MATCH($E31,Prijzen!$B$2:$B$11,0),MATCH($F31,Prijzen!$C$1:$P$1,0))*0.58,0)),$G31*INDEX(Prijzen!$C$73:$P$94,MATCH($E31,Prijzen!$B$73:$B$94,0),MATCH($F31,Prijzen!$C$72:$P$72,0))),0) | J31: =IF($H31="","nog te plannen",IFERROR(LOOKUP($H31,Periodetrend!$B$5:$B$17,Periodetrend!$A$5:$A$17),"vóór P1"))
I32: =IFERROR(IF($C32="UV",IF($D32="S+ liner",$G32*INDEX(Prijzen!$C$15:$P$70,MATCH($E32,Prijzen!$B$15:$B$70,0),MATCH($F32,Prijzen!$C$14:$O$14,0))*0.58,IF($D32="M liner",$G32*INDEX(Prijzen!$C$2:$P$11,MATCH($E32,Prijzen!$B$2:$B$11,0),MATCH($F32,Prijzen!$C$1:$P$1,0))*0.58,0)),$G32*INDEX(Prijzen!$C$73:$P$94,MATCH($E32,Prijzen!$B$73:$B$94,0),MATCH($F32,Prijzen!$C$72:$P$72,0))),0) | J32: =IF($H32="","nog te plannen",IFERROR(LOOKUP($H32,Periodetrend!$B$5:$B$17,Periodetrend!$A$5:$A$17),"vóór P1"))
I33: =IFERROR(IF($C33="UV",IF($D33="S+ liner",$G33*INDEX(Prijzen!$C$15:$P$70,MATCH($E33,Prijzen!$B$15:$B$70,0),MATCH($F33,Prijzen!$C$14:$O$14,0))*0.58,IF($D33="M liner",$G33*INDEX(Prijzen!$C$2:$P$11,MATCH($E33,Prijzen!$B$2:$B$11,0),MATCH($F33,Prijzen!$C$1:$P$1,0))*0.58,0)),$G33*INDEX(Prijzen!$C$73:$P$94,MATCH($E33,Prijzen!$B$73:$B$94,0),MATCH($F33,Prijzen!$C$72:$P$72,0))),0) | J33: =IF($H33="","nog te plannen",IFERROR(LOOKUP($H33,Periodetrend!$B$5:$B$17,Periodetrend!$A$5:$A$17),"vóór P1"))
I34: =IFERROR(IF($C34="UV",IF($D34="S+ liner",$G34*INDEX(Prijzen!$C$15:$P$70,MATCH($E34,Prijzen!$B$15:$B$70,0),MATCH($F34,Prijzen!$C$14:$O$14,0))*0.58,IF($D34="M liner",$G34*INDEX(Prijzen!$C$2:$P$11,MATCH($E34,Prijzen!$B$2:$B$11,0),MATCH($F34,Prijzen!$C$1:$P$1,0))*0.58,0)),$G34*INDEX(Prijzen!$C$73:$P$94,MATCH($E34,Prijzen!$B$73:$B$94,0),MATCH($F34,Prijzen!$C$72:$P$72,0))),0) | J34: =IF($H34="","nog te plannen",IFERROR(LOOKUP($H34,Periodetrend!$B$5:$B$17,Periodetrend!$A$5:$A$17),"vóór P1"))
I35: =IFERROR(IF($C35="UV",IF($D35="S+ liner",$G35*INDEX(Prijzen!$C$15:$P$70,MATCH($E35,Prijzen!$B$15:$B$70,0),MATCH($F35,Prijzen!$C$14:$O$14,0))*0.58,IF($D35="M liner",$G35*INDEX(Prijzen!$C$2:$P$11,MATCH($E35,Prijzen!$B$2:$B$11,0),MATCH($F35,Prijzen!$C$1:$P$1,0))*0.58,0)),$G35*INDEX(Prijzen!$C$73:$P$94,MATCH($E35,Prijzen!$B$73:$B$94,0),MATCH($F35,Prijzen!$C$72:$P$72,0))),0) | J35: =IF($H35="","nog te plannen",IFERROR(LOOKUP($H35,Periodetrend!$B$5:$B$17,Periodetrend!$A$5:$A$17),"vóór P1"))
I36: =IFERROR(IF($C36="UV",IF($D36="S+ liner",$G36*INDEX(Prijzen!$C$15:$P$70,MATCH($E36,Prijzen!$B$15:$B$70,0),MATCH($F36,Prijzen!$C$14:$O$14,0))*0.58,IF($D36="M liner",$G36*INDEX(Prijzen!$C$2:$P$11,MATCH($E36,Prijzen!$B$2:$B$11,0),MATCH($F36,Prijzen!$C$1:$P$1,0))*0.58,0)),$G36*INDEX(Prijzen!$C$73:$P$94,MATCH($E36,Prijzen!$B$73:$B$94,0),MATCH($F36,Prijzen!$C$72:$P$72,0))),0) | J36: =IF($H36="","nog te plannen",IFERROR(LOOKUP($H36,Periodetrend!$B$5:$B$17,Periodetrend!$A$5:$A$17),"vóór P1"))
I37: =IFERROR(IF($C37="UV",IF($D37="S+ liner",$G37*INDEX(Prijzen!$C$15:$P$70,MATCH($E37,Prijzen!$B$15:$B$70,0),MATCH($F37,Prijzen!$C$14:$O$14,0))*0.58,IF($D37="M liner",$G37*INDEX(Prijzen!$C$2:$P$11,MATCH($E37,Prijzen!$B$2:$B$11,0),MATCH($F37,Prijzen!$C$1:$P$1,0))*0.58,0)),$G37*INDEX(Prijzen!$C$73:$P$94,MATCH($E37,Prijzen!$B$73:$B$94,0),MATCH($F37,Prijzen!$C$72:$P$72,0))),0) | J37: =IF($H37="","nog te plannen",IFERROR(LOOKUP($H37,Periodetrend!$B$5:$B$17,Periodetrend!$A$5:$A$17),"vóór P1"))
I38: =IFERROR(IF($C38="UV",IF($D38="S+ liner",$G38*INDEX(Prijzen!$C$15:$P$70,MATCH($E38,Prijzen!$B$15:$B$70,0),MATCH($F38,Prijzen!$C$14:$O$14,0))*0.58,IF($D38="M liner",$G38*INDEX(Prijzen!$C$2:$P$11,MATCH($E38,Prijzen!$B$2:$B$11,0),MATCH($F38,Prijzen!$C$1:$P$1,0))*0.58,0)),$G38*INDEX(Prijzen!$C$73:$P$94,MATCH($E38,Prijzen!$B$73:$B$94,0),MATCH($F38,Prijzen!$C$72:$P$72,0))),0) | J38: =IF($H38="","nog te plannen",IFERROR(LOOKUP($H38,Periodetrend!$B$5:$B$17,Periodetrend!$A$5:$A$17),"vóór P1"))
I39: =IFERROR(IF($C39="UV",IF($D39="S+ liner",$G39*INDEX(Prijzen!$C$15:$P$70,MATCH($E39,Prijzen!$B$15:$B$70,0),MATCH($F39,Prijzen!$C$14:$O$14,0))*0.58,IF($D39="M liner",$G39*INDEX(Prijzen!$C$2:$P$11,MATCH($E39,Prijzen!$B$2:$B$11,0),MATCH($F39,Prijzen!$C$1:$P$1,0))*0.58,0)),$G39*INDEX(Prijzen!$C$73:$P$94,MATCH($E39,Prijzen!$B$73:$B$94,0),MATCH($F39,Prijzen!$C$72:$P$72,0))),0) | J39: =IF($H39="","nog te plannen",IFERROR(LOOKUP($H39,Periodetrend!$B$5:$B$17,Periodetrend!$A$5:$A$17),"vóór P1"))
I40: =IFERROR(IF($C40="UV",IF($D40="S+ liner",$G40*INDEX(Prijzen!$C$15:$P$70,MATCH($E40,Prijzen!$B$15:$B$70,0),MATCH($F40,Prijzen!$C$14:$O$14,0))*0.58,IF($D40="M liner",$G40*INDEX(Prijzen!$C$2:$P$11,MATCH($E40,Prijzen!$B$2:$B$11,0),MATCH($F40,Prijzen!$C$1:$P$1,0))*0.58,0)),$G40*INDEX(Prijzen!$C$73:$P$94,MATCH($E40,Prijzen!$B$73:$B$94,0),MATCH($F40,Prijzen!$C$72:$P$72,0))),0) | J40: =IF($H40="","nog te plannen",IFERROR(LOOKUP($H40,Periodetrend!$B$5:$B$17,Periodetrend!$A$5:$A$17),"vóór P1"))
I41: =IFERROR(IF($C41="UV",IF($D41="S+ liner",$G41*INDEX(Prijzen!$C$15:$P$70,MATCH($E41,Prijzen!$B$15:$B$70,0),MATCH($F41,Prijzen!$C$14:$O$14,0))*0.58,IF($D41="M liner",$G41*INDEX(Prijzen!$C$2:$P$11,MATCH($E41,Prijzen!$B$2:$B$11,0),MATCH($F41,Prijzen!$C$1:$P$1,0))*0.58,0)),$G41*INDEX(Prijzen!$C$73:$P$94,MATCH($E41,Prijzen!$B$73:$B$94,0),MATCH($F41,Prijzen!$C$72:$P$72,0))),0) | J41: =IF($H41="","nog te plannen",IFERROR(LOOKUP($H41,Periodetrend!$B$5:$B$17,Periodetrend!$A$5:$A$17),"vóór P1"))
... I80: =IFERROR(IF($C80="UV",IF($D80="S+ liner",$G80*INDEX(Prijzen!$C$15:$P$70,MATCH($E80,Prijzen!$B$15:$B$70,0),MATCH($F80,Prijzen!$C$14:$O$14,0))*0.58,IF($D80="M liner",$G80*INDEX(Prijzen!$C$2:$P$11,MATCH($E80,Prijzen!$B$2:$B$11,0),MATCH($F80,Prijzen!$C$1:$P$1,0))*0.58,0)),$G80*INDEX(Prijzen!$C$73:$P$94,MATCH($E80,Prijzen!$B$73:$B$94,0),MATCH($F80,Prijzen!$C$72:$P$72,0))),0) | J80: =IF($H80="","nog te plannen",IFERROR(LOOKUP($H80,Periodetrend!$B$5:$B$17,Periodetrend!$A$5:$A$17),"vóór P1"))
H81: TOTAAL | I81: =SUM(I5:I80)

Sheet Calculatie
A1: ALGEMEEN — projectgegevens
A2: Projectnummer
A3: Project
A4: Opdrachtgever
A6: Aanneemsom
A7: Aanneemsom (excl. btw)
A9: Afwijking | B9: hvh/eenh. | C9: eenh. | D9: Prijs per eenh. | E9: aantal | F9: Totaal
A10: Meer putten | B10: 1 | C10: EUR | E10: 1 | F10: =+B10*D10
A11: Meer grondwerk | B11: 1 | C11: EUR | D11: 0 | E11: 1 | F11: =+B11*D11
A12: Meer verkeersmaatregelen | B12: 1 | C12: EUR | D12: 0 | E12: 1 | F12: =+B12*D12
B13: 1 | C13: EUR | D13: 0 | E13: 1 | F13: =+B13*D13
B14: 1 | C14: EUR | D14: 0 | E14: 1 | F14: =+B14*D14
B15: 1 | C15: EUR | D15: 0 | E15: 1 | F15: =+B15*D15
B16: 1 | C16: EUR | D16: 0 | E16: 1 | F16: =+B16*D16
B17: 1 | C17: EUR | D17: 0 | E17: 1 | F17: =+B17*D17
B18: 1 | C18: EUR | D18: 0 | E18: 1 | F18: =+B18*D18
B19: 1 | C19: EUR | D19: 0 | E19: 1 | F19: =+B19*D19
B20: 1 | C20: EUR | D20: 0 | E20: 1 | F20: =+B20*D20
B21: 1 | C21: EUR | D21: 0 | E21: 1 | F21: =+B21*D21
B22: 1 | C22: EUR | D22: 0 | E22: 1 | F22: =+B22*D22
A24: Gecorrigeerde aanneemsom | F24: =SUM(F7:F22)
A26: Verrekende termijnen
A27: Termijn 1 | B27: 1 | C27: EUR | D27: 0 | E27: 1 | F27: =+B27*D27
A28: Termijn 2 | B28: 1 | C28: EUR | D28: 0 | E28: 1 | F28: =+B28*D28
A29: Termijn 3 | B29: 1 | C29: EUR | D29: 0 | E29: 1 | F29: =+B29*D29
A30: Termijn 4 | B30: 1 | C30: EUR | D30: 0 | E30: 1 | F30: =+B30*D30
A31: Termijn 5 | B31: 1 | C31: EUR | D31: 0 | E31: 1 | F31: =+B31*D31
A33: Totaal gefactueerd | F33: =SUM(F27:F31)
A35: Nog te factureren | F35: =F24-F33
A38: Kosten
A39: Geboekte kosten t/m deze periode
A40: Geboekte kosten t/m deze periode | F40: 4907
A42: Nog te boeken kosten deze periode | B42: hvh/eenh. | C42: eenh. | D42: Prijs per eenh. | E42: aantal | F42: Totaal
C43: EUR | D43: 1 | E43: 1 | F43: =B43*D43*E43
F45: 0
A47: subtotaal | F47: =SUM(F43:F45)
A49: Algemenkosten 10% | B49: 10 | C49: % | F49: =SUM(F43:F46)*B49%
A51: Totaal nog te boeken kosten t/m deze periode | F51: =SUM(F47:F49)
A53: Prognose kosten nog uit te voeren/Verwachte kosten
A54: Verwachte kosten — blauwe prijscellen zijn gekoppeld aan 'Tarieven 2026' (schakel Hoog/Laag daar).
...

Sheet Periode-sjabloon
A1: PERIODE-SJABLOON — kopieer dit blad per periode en hernoem (bv. 'Periode 2024-02')
A2: Projectnummer
A3: Project
A4: Opdrachtgever
A6: Aanneemsom
A7: Aanneemsom (excl. btw)
A9: Afwijking | B9: hvh/eenh. | C9: eenh. | D9: Prijs per eenh. | E9: aantal | F9: Totaal
A10: Meer putten | B10: 1 | C10: EUR | E10: 1 | F10: =+B10*D10
A11: Meer grondwerk | B11: 1 | C11: EUR | D11: 0 | E11: 1 | F11: =+B11*D11
A12: Meer verkeersmaatregelen | B12: 1 | C12: EUR | D12: 0 | E12: 1 | F12: =+B12*D12
B13: 1 | C13: EUR | D13: 0 | E13: 1 | F13: =+B13*D13
B14: 1 | C14: EUR | D14: 0 | E14: 1 | F14: =+B14*D14
B15: 1 | C15: EUR | D15: 0 | E15: 1 | F15: =+B15*D15
B16: 1 | C16: EUR | D16: 0 | E16: 1 | F16: =+B16*D16
B17: 1 | C17: EUR | D17: 0 | E17: 1 | F17: =+B17*D17
B18: 1 | C18: EUR | D18: 0 | E18: 1 | F18: =+B18*D18
B19: 1 | C19: EUR | D19: 0 | E19: 1 | F19: =+B19*D19
B20: 1 | C20: EUR | D20: 0 | E20: 1 | F20: =+B20*D20
B21: 1 | C21: EUR | D21: 0 | E21: 1 | F21: =+B21*D21
B22: 1 | C22: EUR | D22: 0 | E22: 1 | F22: =+B22*D22
A24: Gecorrigeerde aanneemsom | F24: =SUM(F7:F22)
A26: Verrekende termijnen
A27: Termijn 1 | B27: 1 | C27: EUR | D27: 0 | E27: 1 | F27: =+B27*D27
A28: Termijn 2 | B28: 1 | C28: EUR | D28: 0 | E28: 1 | F28: =+B28*D28
A29: Termijn 3 | B29: 1 | C29: EUR | D29: 0 | E29: 1 | F29: =+B29*D29
A30: Termijn 4 | B30: 1 | C30: EUR | D30: 0 | E30: 1 | F30: =+B30*D30
A31: Termijn 5 | B31: 1 | C31: EUR | D31: 0 | E31: 1 | F31: =+B31*D31
A33: Totaal gefactueerd | F33: =SUM(F27:F31)
A35: Nog te factureren | F35: =F24-F33
A38: Kosten
A39: Geboekte kosten t/m deze periode
A40: Geboekte kosten t/m deze periode | F40: 0
A42: Nog te boeken kosten deze periode | B42: hvh/eenh. | C42: eenh. | D42: Prijs per eenh. | E42: aantal | F42: Totaal
C43: EUR | D43: 1 | E43: 1 | F43: =B43*D43*E43
F45: 0
A47: subtotaal | F47: =SUM(F43:F45)
A49: Algemenkosten 10% | B49: 10 | C49: % | F49: =SUM(F43:F46)*B49%
A51: Totaal nog te boeken kosten t/m deze periode | F51: =SUM(F47:F49)
A53: Prognose kosten nog uit te voeren/Verwachte kosten
A54: Verwachte kosten — blauwe prijscellen zijn gekoppeld aan 'Tarieven 2026' (schakel Hoog/Laag daar).
...

Sheet Prijzen
B1: M-Liner DN | C1: 3 | D1: 4 | R1: JK | S1: JK RV | X1: nieuw | Y1: 50 | Z1: ploeg per uur | AA1: uitvoerder (max 8 uur) | AB1: project.ldr (max 8 uur) | AD1: Werkdag van | AE1: Totale kosten / dag | AO1: M-Liner | AP1: 3 | AQ1: 4
B2: 100 | C2: =IF(AP2+(AP2*$AL$11)=0,"",AP2+(AP2*$AL$11)) | D2: =IF(AQ2+(AQ2*$AL$11)=0,"",AQ2+(AQ2*$AL$11)) | R2: 13.11 | S2: 35.52 | X2: oud | Y2: 45 | AC2: kader | AO2: 100 | AP2: 24.61 | AQ2: 28.84
B3: 150 | C3: =IF(AP3+(AP3*$AL$11)=0,"",AP3+(AP3*$AL$11)) | D3: =IF(AQ3+(AQ3*$AL$11)=0,"",AQ3+(AQ3*$AL$11)) | R3: 14 | S3: 36.36 | X3: materieel | Y3: man | AC3: per uur | AJ3: 2022 PRIJZEN | AO3: 150 | AP3: 30.03 | AQ3: 34.19
B4: 200 | C4: =IF(AP4+(AP4*$AL$11)=0,"",AP4+(AP4*$AL$11)) | D4: =IF(AQ4+(AQ4*$AL$11)=0,"",AQ4+(AQ4*$AL$11)) | R4: 15.66 | S4: 37.04 | V4: 1 | W4: =_xlfn.CONCAT("Kleine waterset (",Y4," man)") | X4: 175.2 | Y4: 4 | Z4: =SUM((Y4*$Y$2)+X4) | AA4: 55 | AB4: 63 | AC4: =AA4+AB4 | AD4: 10 | AE4: =SUM((IF(AD4>8,(SUM(AB4+AA4)*8),(SUM(AB4+AA4)*AD4)))+(Z4*AD4)) | AO4: 200 | AP4: 36.31 | AQ4: 42.28
B5: 225 | C5: =IF(AP5+(AP5*$AL$11)=0,"",AP5+(AP5*$AL$11)) | D5: =IF(AQ5+(AQ5*$AL$11)=0,"",AQ5+(AQ5*$AL$11)) | R5: 15.66 | S5: 37.04 | V5: 1 | W5: =_xlfn.CONCAT("Grote waterset (",Y5," man)") | X5: 211.65 | Y5: 5 | Z5: =SUM((Y5*$Y$2)+X5) | AA5: 55 | AB5: 63 | AC5: =AA5+AB5 | AD5: 10 | AE5: =SUM((IF(AD5>8,(SUM(AB5+AA5)*8),(SUM(AB5+AA5)*AD5)))+(Z5*AD5)) | AO5: 225 | AP5: 39.27 | AQ5: 46.15
B6: 250 | C6: =IF(AP6+(AP6*$AL$11)=0,"",AP6+(AP6*$AL$11)) | D6: =IF(AQ6+(AQ6*$AL$11)=0,"",AQ6+(AQ6*$AL$11)) | R6: 16.76 | S6: 39.48 | V6: 1 | W6: =_xlfn.CONCAT("Grote waterset (",Y6," man)") | X6: 211.65 | Y6: 4 | Z6: =SUM((Y6*$Y$2)+X6) | AA6: 55 | AB6: 63 | AC6: =AA6+AB6 | AD6: 10 | AE6: =SUM((IF(AD6>8,(SUM(AB6+AA6)*8),(SUM(AB6+AA6)*AD6)))+(Z6*AD6)) | AO6: 250 | AP6: 42.49 | AQ6: 50.23
B7: 300 | C7: =IF(AP7+(AP7*$AL$11)=0,"",AP7+(AP7*$AL$11)) | D7: =IF(AQ7+(AQ7*$AL$11)=0,"",AQ7+(AQ7*$AL$11)) | R7: 18.2 | S7: 40.5 | V7: 1 | W7: =_xlfn.CONCAT("Kleine stoomset (",Y7," man)") | X7: 134.55 | Y7: 4 | Z7: =SUM((Y7*$Y$2)+X7) | AA7: 55 | AB7: 63 | AC7: =AA7+AB7 | AD7: 10 | AE7: =SUM((IF(AD7>8,(SUM(AB7+AA7)*8),(SUM(AB7+AA7)*AD7)))+(Z7*AD7)) | AJ7: vanaf 1 maart 2022 | AO7: 300 | AP7: 48.88 | AQ7: 58.44
B8: 250/375 | C8: =IF(AP8+(AP8*$AL$11)=0,"",AP8+(AP8*$AL$11)) | D8: =IF(AQ8+(AQ8*$AL$11)=0,"",AQ8+(AQ8*$AL$11)) | R8: 18.5 | S8: 41.46 | V8: 1 | W8: =_xlfn.CONCAT("Grote stoomset (",Y8," man)") | X8: 227.5 | Y8: 5 | Z8: =SUM((Y8*$Y$2)+X8) | AA8: 55 | AB8: 63 | AC8: =AA8+AB8 | AD8: 10 | AE8: =SUM((IF(AD8>8,(SUM(AB8+AA8)*8),(SUM(AB8+AA8)*AD8)))+(Z8*AD8)) | AO8: 250/375 | AQ8: 61.75
B9: 350 | C9: =IF(AP9+(AP9*$AL$11)=0,"",AP9+(AP9*$AL$11)) | D9: =IF(AQ9+(AQ9*$AL$11)=0,"",AQ9+(AQ9*$AL$11)) | R9: 20.48 | S9: 41.46 | V9: 2 | W9: =_xlfn.CONCAT("UV-set (incl. combi) (",Y9," man)") | X9: 215 | Y9: 5 | Z9: =SUM((Y9*$Y$2)+X9) | AA9: 55 | AB9: 63 | AC9: =AA9+AB9 | AD9: 10 | AE9: =SUM((IF(AD9>8,(SUM(AB9+AA9)*8),(SUM(AB9+AA9)*AD9)))+(Z9*AD9)) | AO9: 350 | AP9: 55.13 | AQ9: 66.48
B10: 300/450 | C10: =IF(AP10+(AP10*$AL$11)=0,"",AP10+(AP10*$AL$11)) | D10: =IF(AQ10+(AQ10*$AL$11)=0,"",AQ10+(AQ10*$AL$11)) | R10: 22.73 | S10: 43.61 | V10: 2 | W10: =_xlfn.CONCAT("UV-set (excl. combi) (",Y10," man)") | X10: 215 | Y10: 4 | Z10: 415 | AA10: 55 | AB10: 63 | AC10: =AA10+AB10 | AD10: 10 | AE10: =SUM((IF(AD10>8,(SUM(AB10+AA10)*8),(SUM(AB10+AA10)*AD10)))+(Z10*AD10)) | AO10: 300/450 | AP10: 58.74 | AQ10: 71.11
B11: 400 | C11: =IF(AP11+(AP11*$AL$11)=0,"",AP11+(AP11*$AL$11)) | D11: =IF(AQ11+(AQ11*$AL$11)=0,"",AQ11+(AQ11*$AL$11)) | R11: 22.73 | S11: 43.61 | V11: 5 | W11: Inspectie (eigen) | Z11: 105 | AK11: Index % (M/S+ liner) | AL11: 0.08 | AO11: 400 | AP11: 61.43 | AQ11: 74.61
V12: 5 | W12: Inspectie | Z12: 145
B13: 44725 | V13: 3 | W13: Combi (eigen) | X13: 70 | Y13: 1 | Z13: =SUM((Y13*$Y$2)+X13) | AC13: =AA13+AB13 | AD13: 10 | AE13: =SUM((IF(AD13>8,(SUM(AB13+AA13)*8),(SUM(AB13+AA13)*AD13)))+(Z13*AD13)) | AJ13: 44682
B14: S+ Liner DN | C14: 3 | D14: 4 | E14: 5 | F14: 6 | G14: 7 | H14: 8 | I14: 9 | J14: 10 | K14: 11 | L14: 12 | M14: 13 | N14: 14 | O14: 15 | Q14: diameter | R14: JK | S14: JK RV | V14: 3 | W14: Reiniging Combi | X14: 90 | Y14: 1 | Z14: =SUM((Y14*$Y$2)+X14) | AC14: =AA14+AB14 | AD14: 10 | AE14: =SUM((IF(AD14>8,(SUM(AB14+AA14)*8),(SUM(AB14+AA14)*AD14)))+(Z14*AD14)) | AJ14: S+ Liner | AK14: 3 | AL14: 4 | AM14: 5 | AN14: 6 | AO14: 7 | AP14: 8 | AQ14: 9 | AR14: 10 | AS14: 11 | AT14: 12 | AU14: 13 | AV14: 14 | AW14: 15
B15: 150 | C15: =IFERROR(IF(AK15+(AK15*$AL$11)=0,"",AK15+(AK15*$AL$11)),"") | D15: =IFERROR(IF(AL15+(AL15*$AL$11)=0,"",AL15+(AL15*$AL$11)),"") | E15: =IFERROR(IF(AM15+(AM15*$AL$11)=0,"",AM15+(AM15*$AL$11)),"") | F15: =IFERROR(IF(AN15+(AN15*$AL$11)=0,"",AN15+(AN15*$AL$11)),"") | G15: =IFERROR(IF(AO15+(AO15*$AL$11)=0,"",AO15+(AO15*$AL$11)),"") | H15: =IFERROR(IF(AP15+(AP15*$AL$11)=0,"",AP15+(AP15*$AL$11)),"") | I15: =IFERROR(IF(AQ15+(AQ15*$AL$11)=0,"",AQ15+(AQ15*$AL$11)),"") | J15: =IFERROR(IF(AR15+(AR15*$AL$11)=0,"",AR15+(AR15*$AL$11)),"") | ... O15: =IFERROR(IF(AW15+(AW15*$AL$11)=0,"",AW15+(AW15*$AL$11)),"") | Q15: 150 | R15: 13.11 | S15: 35.52 | V15: 4 | W15: =_xlfn.CONCAT("Freesunit (",Y15," man)") | X15: 78 | Y15: 2 | Z15: 168 | AC15: =AA15+AB15 | AD15: 10 | AE15: =SUM((IF(AD15>8,(SUM(AB15+AA15)*8),(SUM(AB15+AA15)*AD15)))+(Z15*AD15)) | AJ15: 150 | AK15: 41.1712 | AL15: 50.5344
B16: 200 | C16: =IFERROR(IF(AK16+(AK16*$AL$11)=0,"",AK16+(AK16*$AL$11)),"") | D16: =IFERROR(IF(AL16+(AL16*$AL$11)=0,"",AL16+(AL16*$AL$11)),"") | E16: =IFERROR(IF(AM16+(AM16*$AL$11)=0,"",AM16+(AM16*$AL$11)),"") | F16: =IFERROR(IF(AN16+(AN16*$AL$11)=0,"",AN16+(AN16*$AL$11)),"") | G16: =IFERROR(IF(AO16+(AO16*$AL$11)=0,"",AO16+(AO16*$AL$11)),"") | H16: =IFERROR(IF(AP16+(AP16*$AL$11)=0,"",AP16+(AP16*$AL$11)),"") | I16: =IFERROR(IF(AQ16+(AQ16*$AL$11)=0,"",AQ16+(AQ16*$AL$11)),"") | J16: =IFERROR(IF(AR16+(AR16*$AL$11)=0,"",AR16+(AR16*$AL$11)),"") | ... O16: =IFERROR(IF(AW16+(AW16*$AL$11)=0,"",AW16+(AW16*$AL$11)),"") | Q16: 200 | R16: 14 | S16: 36.36 | V16: 1 | W16: =_xlfn.CONCAT("1 Kleine waterset (",Y16," man)") | X16: 175.2 | Y16: 4 | Z16: =SUM((Y16*$Y$1)+X16) | AC16: =AA16+AB16 | AD16: 10 | AE16: =SUM((IF(AD16>8,(SUM(AB16+AA16)*8),(SUM(AB16+AA16)*AD16)))+(Z16*AD16)) | AJ16: 200 | AK16: 49.784 | AL16: 63.0336 | AM16: 74.4352 | AN16: 81.8832
B17: 225 | C17: =IFERROR(IF(AK17+(AK17*$AL$11)=0,"",AK17+(AK17*$AL$11)),"") | D17: =IFERROR(IF(AL17+(AL17*$AL$11)=0,"",AL17+(AL17*$AL$11)),"") | E17: =IFERROR(IF(AM17+(AM17*$AL$11)=0,"",AM17+(AM17*$AL$11)),"") | F17: =IFERROR(IF(AN17+(AN17*$AL$11)=0,"",AN17+(AN17*$AL$11)),"") | G17: =IFERROR(IF(AO17+(AO17*$AL$11)=0,"",AO17+(AO17*$AL$11)),"") | H17: =IFERROR(IF(AP17+(AP17*$AL$11)=0,"",AP17+(AP17*$AL$11)),"") | I17: =IFERROR(IF(AQ17+(AQ17*$AL$11)=0,"",AQ17+(AQ17*$AL$11)),"") | J17: =IFERROR(IF(AR17+(AR17*$AL$11)=0,"",AR17+(AR17*$AL$11)),"") | ... O17: =IFERROR(IF(AW17+(AW17*$AL$11)=0,"",AW17+(AW17*$AL$11)),"") | Q17: 225 | R17: 15.66 | S17: 37.04 | V17: 1 | W17: =_xlfn.CONCAT("1 Kleine waterset (",Y17," man)") | X17: 175.2 | Y17: 5 | Z17: =SUM((Y17*$Y$1)+X17) | AC17: =AA17+AB17 | AD17: 10 | AE17: =SUM((IF(AD17>8,(SUM(AB17+AA17)*8),(SUM(AB17+AA17)*AD17)))+(Z17*AD17)) | AJ17: 225 | AK17: 53.8384 | AL17: 69.2832 | AM17: 81.5248 | AN17: 89.9584
B18: 230 | C18: =IFERROR(IF(AK18+(AK18*$AL$11)=0,"",AK18+(AK18*$AL$11)),"") | D18: =IFERROR(IF(AL18+(AL18*$AL$11)=0,"",AL18+(AL18*$AL$11)),"") | E18: =IFERROR(IF(AM18+(AM18*$AL$11)=0,"",AM18+(AM18*$AL$11)),"") | F18: =IFERROR(IF(AN18+(AN18*$AL$11)=0,"",AN18+(AN18*$AL$11)),"") | G18: =IFERROR(IF(AO18+(AO18*$AL$11)=0,"",AO18+(AO18*$AL$11)),"") | H18: =IFERROR(IF(AP18+(AP18*$AL$11)=0,"",AP18+(AP18*$AL$11)),"") | I18: =IFERROR(IF(AQ18+(AQ18*$AL$11)=0,"",AQ18+(AQ18*$AL$11)),"") | J18: =IFERROR(IF(AR18+(AR18*$AL$11)=0,"",AR18+(AR18*$AL$11)),"") | ... O18: =IFERROR(IF(AW18+(AW18*$AL$11)=0,"",AW18+(AW18*$AL$11)),"") | Q18: 230 | R18: 15.66 | S18: 37.04 | V18: 1 | W18: =_xlfn.CONCAT("1 Grote waterset (",Y18," man)") | X18: 211.65 | Y18: 4 | Z18: =SUM((Y18*$Y$1)+X18) | AC18: =AA18+AB18 | AD18: 10 | AE18: =SUM((IF(AD18>8,(SUM(AB18+AA18)*8),(SUM(AB18+AA18)*AD18)))+(Z18*AD18)) | AJ18: 230
B19: 250 | C19: =IFERROR(IF(AK19+(AK19*$AL$11)=0,"",AK19+(AK19*$AL$11)),"") | D19: =IFERROR(IF(AL19+(AL19*$AL$11)=0,"",AL19+(AL19*$AL$11)),"") | E19: =IFERROR(IF(AM19+(AM19*$AL$11)=0,"",AM19+(AM19*$AL$11)),"") | F19: =IFERROR(IF(AN19+(AN19*$AL$11)=0,"",AN19+(AN19*$AL$11)),"") | G19: =IFERROR(IF(AO19+(AO19*$AL$11)=0,"",AO19+(AO19*$AL$11)),"") | H19: =IFERROR(IF(AP19+(AP19*$AL$11)=0,"",AP19+(AP19*$AL$11)),"") | I19: =IFERROR(IF(AQ19+(AQ19*$AL$11)=0,"",AQ19+(AQ19*$AL$11)),"") | J19: =IFERROR(IF(AR19+(AR19*$AL$11)=0,"",AR19+(AR19*$AL$11)),"") | ... O19: =IFERROR(IF(AW19+(AW19*$AL$11)=0,"",AW19+(AW19*$AL$11)),"") | Q19: 250 | R19: 16.76 | S19: 39.48 | V19: 1 | W19: =_xlfn.CONCAT("1 Grote waterset (",Y19," man)") | X19: 211.65 | Y19: 5 | Z19: =SUM((Y19*$Y$1)+X19) | AC19: =AA19+AB19 | AD19: 10 | AE19: =SUM((IF(AD19>8,(SUM(AB19+AA19)*8),(SUM(AB19+AA19)*AD19)))+(Z19*AD19)) | AJ19: 250 | AK19: 58.2512 | AL19: 75.5328 | AM19: 88.6144 | AN19: 98.0448
B20: 200/300 | C20: =IFERROR(IF(AK20+(AK20*$AL$11)=0,"",AK20+(AK20*$AL$11)),"") | D20: =IFERROR(IF(AL20+(AL20*$AL$11)=0,"",AL20+(AL20*$AL$11)),"") | E20: =IFERROR(IF(AM20+(AM20*$AL$11)=0,"",AM20+(AM20*$AL$11)),"") | F20: =IFERROR(IF(AN20+(AN20*$AL$11)=0,"",AN20+(AN20*$AL$11)),"") | V20: 1 | W20: =_xlfn.CONCAT("1 Kleine stoomset (",Y20," man)") | X20: 134.55 | Y20: 4 | Z20: =SUM((Y20*$Y$2)+X20) | AC20: =AA20+AB20 | AD20: 10 | AE20: =SUM((IF(AD20>8,(SUM(AB20+AA20)*8),(SUM(AB20+AA20)*AD20)))+(Z20*AD20)) | AJ20: 200/300 | AK20: 69.1488 | AL20: 80.1136 | AM20: 88.6144 | AN20: 98.0448
B21: 252 | C21: =IFERROR(IF(AK21+(AK21*$AL$11)=0,"",AK21+(AK21*$AL$11)),"") | D21: =IFERROR(IF(AL21+(AL21*$AL$11)=0,"",AL21+(AL21*$AL$11)),"") | E21: =IFERROR(IF(AM21+(AM21*$AL$11)=0,"",AM21+(AM21*$AL$11)),"") | F21: =IFERROR(IF(AN21+(AN21*$AL$11)=0,"",AN21+(AN21*$AL$11)),"") | V21: 1 | W21: =_xlfn.CONCAT("1 Kleine stoomset (",Y21," man)") | X21: 134.55 | Y21: 5 | Z21: =SUM((Y21*$Y$2)+X21) | AC21: =AA21+AB21 | AD21: 10 | AE21: =SUM((IF(AD21>8,(SUM(AB21+AA21)*8),(SUM(AB21+AA21)*AD21)))+(Z21*AD21)) | AJ21: 252 | AK21: 69.1488 | AL21: 80.1136 | AM21: 88.6144 | AN21: 98.0448
B22: 300 | C22: =IFERROR(IF(AK22+(AK22*$AL$11)=0,"",AK22+(AK22*$AL$11)),"") | D22: =IFERROR(IF(AL22+(AL22*$AL$11)=0,"",AL22+(AL22*$AL$11)),"") | E22: =IFERROR(IF(AM22+(AM22*$AL$11)=0,"",AM22+(AM22*$AL$11)),"") | F22: =IFERROR(IF(AN22+(AN22*$AL$11)=0,"",AN22+(AN22*$AL$11)),"") | G22: =IFERROR(IF(AO22+(AO22*$AL$11)=0,"",AO22+(AO22*$AL$11)),"") | H22: =IFERROR(IF(AP22+(AP22*$AL$11)=0,"",AP22+(AP22*$AL$11)),"") | I22: =IFERROR(IF(AQ22+(AQ22*$AL$11)=0,"",AQ22+(AQ22*$AL$11)),"") | J22: =IFERROR(IF(AR22+(AR22*$AL$11)=0,"",AR22+(AR22*$AL$11)),"") | ... O22: =IFERROR(IF(AW22+(AW22*$AL$11)=0,"",AW22+(AW22*$AL$11)),"") | Q22: 300 | R22: 18.2 | S22: 40.5 | V22: 1 | W22: =_xlfn.CONCAT("1 Grote stoomset (",Y22," man)") | X22: 227.5 | Y22: 5 | Z22: =SUM((Y22*$Y$1)+X22) | AC22: =AA22+AB22 | AD22: 10 | AE22: =SUM((IF(AD22>8,(SUM(AB22+AA22)*8),(SUM(AB22+AA22)*AD22)))+(Z22*AD22)) | AJ22: 300 | AK22: 67.0208 | AL22: 88.0208 | AM22: 102.7936 | AN22: 114.2064
B23: 250/375 | C23: =IFERROR(IF(AK23+(AK23*$AL$11)=0,"",AK23+(AK23*$AL$11)),"") | D23: =IFERROR(IF(AL23+(AL23*$AL$11)=0,"",AL23+(AL23*$AL$11)),"") | E23: =IFERROR(IF(AM23+(AM23*$AL$11)=0,"",AM23+(AM23*$AL$11)),"") | F23: =IFERROR(IF(AN23+(AN23*$AL$11)=0,"",AN23+(AN23*$AL$11)),"") | G23: =IFERROR(IF(AO23+(AO23*$AL$11)=0,"",AO23+(AO23*$AL$11)),"") | H23: =IFERROR(IF(AP23+(AP23*$AL$11)=0,"",AP23+(AP23*$AL$11)),"") | I23: =IFERROR(IF(AQ23+(AQ23*$AL$11)=0,"",AQ23+(AQ23*$AL$11)),"") | J23: =IFERROR(IF(AR23+(AR23*$AL$11)=0,"",AR23+(AR23*$AL$11)),"") | ... O23: =IFERROR(IF(AW23+(AW23*$AL$11)=0,"",AW23+(AW23*$AL$11)),"") | Q23: 250/375 | S23: 41.46 | V23: 4 | W23: =_xlfn.CONCAT("1 Freesunit (",Y23," man)") | X23: 85 | Y23: 2 | Z23: =SUM((Y23*$Y$1)+X23) | AC23: =AA23+AB23 | AD23: 10 | AE23: =SUM((IF(AD23>8,(SUM(AB23+AA23)*8),(SUM(AB23+AA23)*AD23)))+(Z23*AD23)) | AJ23: 250/375 | AK23: 83.664 | AL23: 97.0928 | AM23: 106.904 | AN23: 118.7648
B24: 315 | C24: =IFERROR(IF(AK24+(AK24*$AL$11)=0,"",AK24+(AK24*$AL$11)),"") | D24: =IFERROR(IF(AL24+(AL24*$AL$11)=0,"",AL24+(AL24*$AL$11)),"") | E24: =IFERROR(IF(AM24+(AM24*$AL$11)=0,"",AM24+(AM24*$AL$11)),"") | F24: =IFERROR(IF(AN24+(AN24*$AL$11)=0,"",AN24+(AN24*$AL$11)),"") | G24: =IFERROR(IF(AO24+(AO24*$AL$11)=0,"",AO24+(AO24*$AL$11)),"") | H24: =IFERROR(IF(AP24+(AP24*$AL$11)=0,"",AP24+(AP24*$AL$11)),"") | I24: =IFERROR(IF(AQ24+(AQ24*$AL$11)=0,"",AQ24+(AQ24*$AL$11)),"") | J24: =IFERROR(IF(AR24+(AR24*$AL$11)=0,"",AR24+(AR24*$AL$11)),"") | ... O24: =IFERROR(IF(AW24+(AW24*$AL$11)=0,"",AW24+(AW24*$AL$11)),"") | Q24: 317 | R24: 18.5 | S24: 41.46 | V24: 3 | W24: 1 Combi (eigen) | X24: 60 | Y24: 1 | Z24: =SUM((Y24*$Y$1)+X24) | AC24: =AA24+AB24 | AD24: 10 | AE24: =SUM((IF(AD24>8,(SUM(AB24+AA24)*8),(SUM(AB24+AA24)*AD24)))+(Z24*AD24)) | AJ24: 315 | AK24: 83.664 | AL24: 97.0928 | AM24: 106.904 | AN24: 118.7648
B25: 350 | C25: =IFERROR(IF(AK25+(AK25*$AL$11)=0,"",AK25+(AK25*$AL$11)),"") | D25: =IFERROR(IF(AL25+(AL25*$AL$11)=0,"",AL25+(AL25*$AL$11)),"") | E25: =IFERROR(IF(AM25+(AM25*$AL$11)=0,"",AM25+(AM25*$AL$11)),"") | F25: =IFERROR(IF(AN25+(AN25*$AL$11)=0,"",AN25+(AN25*$AL$11)),"") | G25: =IFERROR(IF(AO25+(AO25*$AL$11)=0,"",AO25+(AO25*$AL$11)),"") | H25: =IFERROR(IF(AP25+(AP25*$AL$11)=0,"",AP25+(AP25*$AL$11)),"") | I25: =IFERROR(IF(AQ25+(AQ25*$AL$11)=0,"",AQ25+(AQ25*$AL$11)),"") | J25: =IFERROR(IF(AR25+(AR25*$AL$11)=0,"",AR25+(AR25*$AL$11)),"") | ... O25: =IFERROR(IF(AW25+(AW25*$AL$11)=0,"",AW25+(AW25*$AL$11)),"") | Q25: 350 | R25: 20.48 | S25: 41.46 | V25: 5 | W25: 1 Inspectie (eigen) | X25: 55 | Y25: 1 | Z25: =SUM((Y25*$Y$1)+X25) | AC25: =AA25+AB25 | AD25: 10 | AE25: =SUM((IF(AD25>8,(SUM(AB25+AA25)*8),(SUM(AB25+AA25)*AD25)))+(Z25*AD25)) | AJ25: 350 | AK25: 75.5888 | AL25: 100.5312 | AM25: 116.9728 | AN25: 130.368
B26: 300/450 | C26: =IFERROR(IF(AK26+(AK26*$AL$11)=0,"",AK26+(AK26*$AL$11)),"") | D26: =IFERROR(IF(AL26+(AL26*$AL$11)=0,"",AL26+(AL26*$AL$11)),"") | E26: =IFERROR(IF(AM26+(AM26*$AL$11)=0,"",AM26+(AM26*$AL$11)),"") | F26: =IFERROR(IF(AN26+(AN26*$AL$11)=0,"",AN26+(AN26*$AL$11)),"") | G26: =IFERROR(IF(AO26+(AO26*$AL$11)=0,"",AO26+(AO26*$AL$11)),"") | H26: =IFERROR(IF(AP26+(AP26*$AL$11)=0,"",AP26+(AP26*$AL$11)),"") | I26: =IFERROR(IF(AQ26+(AQ26*$AL$11)=0,"",AQ26+(AQ26*$AL$11)),"") | J26: =IFERROR(IF(AR26+(AR26*$AL$11)=0,"",AR26+(AR26*$AL$11)),"") | ... O26: =IFERROR(IF(AW26+(AW26*$AL$11)=0,"",AW26+(AW26*$AL$11)),"") | Q26: 300/450 | R26: 22.73 | S26: 43.61 | V26: 2 | W26: =_xlfn.CONCAT("1 UV-set (excl. combi) (",Y26," man)") | X26: 244 | Y26: 4 | Z26: =SUM((Y26*$Y$1)+X26) | AC26: =AA26+AB26 | AD26: 10 | AE26: =SUM((IF(AD26>8,(SUM(AB26+AA26)*8),(SUM(AB26+AA26)*AD26)))+(Z26*AD26)) | AJ26: 300/450 | AK26: 97.1152 | AL26: 113.2432 | AM26: 124.0624 | AN26: 138.4544
B27: 378 | C27: =IFERROR(IF(AK27+(AK27*$AL$11)=0,"",AK27+(AK27*$AL$11)),"") | D27: =IFERROR(IF(AL27+(AL27*$AL$11)=0,"",AL27+(AL27*$AL$11)),"") | E27: =IFERROR(IF(AM27+(AM27*$AL$11)=0,"",AM27+(AM27*$AL$11)),"") | F27: =IFERROR(IF(AN27+(AN27*$AL$11)=0,"",AN27+(AN27*$AL$11)),"") | G27: =IFERROR(IF(AO27+(AO27*$AL$11)=0,"",AO27+(AO27*$AL$11)),"") | H27: =IFERROR(IF(AP27+(AP27*$AL$11)=0,"",AP27+(AP27*$AL$11)),"") | I27: =IFERROR(IF(AQ27+(AQ27*$AL$11)=0,"",AQ27+(AQ27*$AL$11)),"") | J27: =IFERROR(IF(AR27+(AR27*$AL$11)=0,"",AR27+(AR27*$AL$11)),"") | ... O27: =IFERROR(IF(AW27+(AW27*$AL$11)=0,"",AW27+(AW27*$AL$11)),"") | Q27: 378 | R27: 22.73 | S27: 43.61 | V27: 2 | W27: =_xlfn.CONCAT("1 UV-set (excl. combi) (",Y27," man)") | X27: 244 | Y27: 5 | Z27: =SUM((Y27*$Y$1)+X27) | AC27: =AA27+AB27 | AD27: 10 | AE27: =SUM((IF(AD27>8,(SUM(AB27+AA27)*8),(SUM(AB27+AA27)*AD27)))+(Z27*AD27)) | AJ27: 378 | AK27: 97.1152 | AL27: 113.2432 | AM27: 124.0624 | AN27: 138.4544
B28: 400 | C28: =IFERROR(IF(AK28+(AK28*$AL$11)=0,"",AK28+(AK28*$AL$11)),"") | D28: =IFERROR(IF(AL28+(AL28*$AL$11)=0,"",AL28+(AL28*$AL$11)),"") | E28: =IFERROR(IF(AM28+(AM28*$AL$11)=0,"",AM28+(AM28*$AL$11)),"") | F28: =IFERROR(IF(AN28+(AN28*$AL$11)=0,"",AN28+(AN28*$AL$11)),"") | G28: =IFERROR(IF(AO28+(AO28*$AL$11)=0,"",AO28+(AO28*$AL$11)),"") | H28: =IFERROR(IF(AP28+(AP28*$AL$11)=0,"",AP28+(AP28*$AL$11)),"") | I28: =IFERROR(IF(AQ28+(AQ28*$AL$11)=0,"",AQ28+(AQ28*$AL$11)),"") | J28: =IFERROR(IF(AR28+(AR28*$AL$11)=0,"",AR28+(AR28*$AL$11)),"") | ... O28: =IFERROR(IF(AW28+(AW28*$AL$11)=0,"",AW28+(AW28*$AL$11)),"") | Q28: 400 | R28: 22.73 | S28: 43.61 | AJ28: 400 | AK28: 84.224 | AL28: 113.0304 | AM28: 131.152 | AN28: 146.5296 | AO28: 166.5552
B29: 350/525 | C29: =IFERROR(IF(AK29+(AK29*$AL$11)=0,"",AK29+(AK29*$AL$11)),"") | D29: =IFERROR(IF(AL29+(AL29*$AL$11)=0,"",AL29+(AL29*$AL$11)),"") | E29: =IFERROR(IF(AM29+(AM29*$AL$11)=0,"",AM29+(AM29*$AL$11)),"") | F29: =IFERROR(IF(AN29+(AN29*$AL$11)=0,"",AN29+(AN29*$AL$11)),"") | G29: =IFERROR(IF(AO29+(AO29*$AL$11)=0,"",AO29+(AO29*$AL$11)),"") | H29: =IFERROR(IF(AP29+(AP29*$AL$11)=0,"",AP29+(AP29*$AL$11)),"") | I29: =IFERROR(IF(AQ29+(AQ29*$AL$11)=0,"",AQ29+(AQ29*$AL$11)),"") | J29: =IFERROR(IF(AR29+(AR29*$AL$11)=0,"",AR29+(AR29*$AL$11)),"") | ... O29: =IFERROR(IF(AW29+(AW29*$AL$11)=0,"",AW29+(AW29*$AL$11)),"") | Q29: 350/525 | R29: 24.83 | S29: 45.83 | W29: UV set | AJ29: 350/525 | AL29: 128.7776 | AM29: 139.3168 | AN29: 159.0736 | AO29: 180.88
B30: 442 | C30: =IFERROR(IF(AK30+(AK30*$AL$11)=0,"",AK30+(AK30*$AL$11)),"") | D30: =IFERROR(IF(AL30+(AL30*$AL$11)=0,"",AL30+(AL30*$AL$11)),"") | E30: =IFERROR(IF(AM30+(AM30*$AL$11)=0,"",AM30+(AM30*$AL$11)),"") | F30: =IFERROR(IF(AN30+(AN30*$AL$11)=0,"",AN30+(AN30*$AL$11)),"") | G30: =IFERROR(IF(AO30+(AO30*$AL$11)=0,"",AO30+(AO30*$AL$11)),"") | H30: =IFERROR(IF(AP30+(AP30*$AL$11)=0,"",AP30+(AP30*$AL$11)),"") | I30: =IFERROR(IF(AQ30+(AQ30*$AL$11)=0,"",AQ30+(AQ30*$AL$11)),"") | J30: =IFERROR(IF(AR30+(AR30*$AL$11)=0,"",AR30+(AR30*$AL$11)),"") | ... O30: =IFERROR(IF(AW30+(AW30*$AL$11)=0,"",AW30+(AW30*$AL$11)),"") | Q30: 441 | R30: 24.83 | S30: 45.83 | W30: Lier | X30: 15 | AJ30: 442 | AL30: 128.7776 | AM30: 139.3168 | AN30: 159.0736 | AO30: 180.88
B31: 450 | C31: =IFERROR(IF(AK31+(AK31*$AL$11)=0,"",AK31+(AK31*$AL$11)),"") | D31: =IFERROR(IF(AL31+(AL31*$AL$11)=0,"",AL31+(AL31*$AL$11)),"") | E31: =IFERROR(IF(AM31+(AM31*$AL$11)=0,"",AM31+(AM31*$AL$11)),"") | F31: =IFERROR(IF(AN31+(AN31*$AL$11)=0,"",AN31+(AN31*$AL$11)),"") | G31: =IFERROR(IF(AO31+(AO31*$AL$11)=0,"",AO31+(AO31*$AL$11)),"") | H31: =IFERROR(IF(AP31+(AP31*$AL$11)=0,"",AP31+(AP31*$AL$11)),"") | I31: =IFERROR(IF(AQ31+(AQ31*$AL$11)=0,"",AQ31+(AQ31*$AL$11)),"") | J31: =IFERROR(IF(AR31+(AR31*$AL$11)=0,"",AR31+(AR31*$AL$11)),"") | ... O31: =IFERROR(IF(AW31+(AW31*$AL$11)=0,"",AW31+(AW31*$AL$11)),"") | Q31: 450 | R31: 24.83 | S31: 45.83 | W31: Bus | X31: 14 | AJ31: 450 | AK31: 114.9344 | AL31: 131.1184 | AM31: 141.848 | AN31: 161.952 | AO31: 184.1504
B32: 500 | C32: =IFERROR(IF(AK32+(AK32*$AL$11)=0,"",AK32+(AK32*$AL$11)),"") | D32: =IFERROR(IF(AL32+(AL32*$AL$11)=0,"",AL32+(AL32*$AL$11)),"") | E32: =IFERROR(IF(AM32+(AM32*$AL$11)=0,"",AM32+(AM32*$AL$11)),"") | F32: =IFERROR(IF(AN32+(AN32*$AL$11)=0,"",AN32+(AN32*$AL$11)),"") | G32: =IFERROR(IF(AO32+(AO32*$AL$11)=0,"",AO32+(AO32*$AL$11)),"") | H32: =IFERROR(IF(AP32+(AP32*$AL$11)=0,"",AP32+(AP32*$AL$11)),"") | I32: =IFERROR(IF(AQ32+(AQ32*$AL$11)=0,"",AQ32+(AQ32*$AL$11)),"") | J32: =IFERROR(IF(AR32+(AR32*$AL$11)=0,"",AR32+(AR32*$AL$11)),"") | ... O32: =IFERROR(IF(AW32+(AW32*$AL$11)=0,"",AW32+(AW32*$AL$11)),"") | Q32: 500 | R32: 27 | S32: 48.05 | W32: UV | X32: 130 | AJ32: 500 | AK32: 127.6352 | AL32: 142.8896 | AM32: 153.1376 | AN32: 178.0464 | AO32: 202.496 | AP32: 231.1792
B33: 400/600 | C33: =IFERROR(IF(AK33+(AK33*$AL$11)=0,"",AK33+(AK33*$AL$11)),"") | D33: =IFERROR(IF(AL33+(AL33*$AL$11)=0,"",AL33+(AL33*$AL$11)),"") | E33: =IFERROR(IF(AM33+(AM33*$AL$11)=0,"",AM33+(AM33*$AL$11)),"") | F33: =IFERROR(IF(AN33+(AN33*$AL$11)=0,"",AN33+(AN33*$AL$11)),"") | G33: =IFERROR(IF(AO33+(AO33*$AL$11)=0,"",AO33+(AO33*$AL$11)),"") | H33: =IFERROR(IF(AP33+(AP33*$AL$11)=0,"",AP33+(AP33*$AL$11)),"") | I33: =IFERROR(IF(AQ33+(AQ33*$AL$11)=0,"",AQ33+(AQ33*$AL$11)),"") | J33: =IFERROR(IF(AR33+(AR33*$AL$11)=0,"",AR33+(AR33*$AL$11)),"") | ... O33: =IFERROR(IF(AW33+(AW33*$AL$11)=0,"",AW33+(AW33*$AL$11)),"") | Q33: 400/600 | R33: 27 | S33: 48.05 | W33: kraan | X33: 85 | AJ33: 400/600 | AL33: 144.3344 | AM33: 154.6608 | AN33: 179.8272 | AO33: 204.5232
B34: 505 | C34: =IFERROR(IF(AK34+(AK34*$AL$11)=0,"",AK34+(AK34*$AL$11)),"") | D34: =IFERROR(IF(AL34+(AL34*$AL$11)=0,"",AL34+(AL34*$AL$11)),"") | E34: =IFERROR(IF(AM34+(AM34*$AL$11)=0,"",AM34+(AM34*$AL$11)),"") | F34: =IFERROR(IF(AN34+(AN34*$AL$11)=0,"",AN34+(AN34*$AL$11)),"") | G34: =IFERROR(IF(AO34+(AO34*$AL$11)=0,"",AO34+(AO34*$AL$11)),"") | H34: =IFERROR(IF(AP34+(AP34*$AL$11)=0,"",AP34+(AP34*$AL$11)),"") | I34: =IFERROR(IF(AQ34+(AQ34*$AL$11)=0,"",AQ34+(AQ34*$AL$11)),"") | J34: =IFERROR(IF(AR34+(AR34*$AL$11)=0,"",AR34+(AR34*$AL$11)),"") | ... O34: =IFERROR(IF(AW34+(AW34*$AL$11)=0,"",AW34+(AW34*$AL$11)),"") | Q34: 505 | R34: 27 | S34: 48.05 | X34: =SUM(X30:X33) | AJ34: 505 | AL34: 144.3344 | AM34: 154.6608 | AN34: 179.8272 | AO34: 204.5232
B35: 550 | C35: =IFERROR(IF(AK35+(AK35*$AL$11)=0,"",AK35+(AK35*$AL$11)),"") | D35: =IFERROR(IF(AL35+(AL35*$AL$11)=0,"",AL35+(AL35*$AL$11)),"") | E35: =IFERROR(IF(AM35+(AM35*$AL$11)=0,"",AM35+(AM35*$AL$11)),"") | F35: =IFERROR(IF(AN35+(AN35*$AL$11)=0,"",AN35+(AN35*$AL$11)),"") | G35: =IFERROR(IF(AO35+(AO35*$AL$11)=0,"",AO35+(AO35*$AL$11)),"") | H35: =IFERROR(IF(AP35+(AP35*$AL$11)=0,"",AP35+(AP35*$AL$11)),"") | I35: =IFERROR(IF(AQ35+(AQ35*$AL$11)=0,"",AQ35+(AQ35*$AL$11)),"") | J35: =IFERROR(IF(AR35+(AR35*$AL$11)=0,"",AR35+(AR35*$AL$11)),"") | ... O35: =IFERROR(IF(AW35+(AW35*$AL$11)=0,"",AW35+(AW35*$AL$11)),"") | Q35: 550 | R35: 29.1 | S35: 49.73 | AJ35: 550 | AK35: 140.336 | AL35: 157.5056 | AM35: 170.072 | AN35: 194.1296 | AO35: 220.8416 | AP35: 251.6528
B36: 600 | C36: =IFERROR(IF(AK36+(AK36*$AL$11)=0,"",AK36+(AK36*$AL$11)),"") | D36: =IFERROR(IF(AL36+(AL36*$AL$11)=0,"",AL36+(AL36*$AL$11)),"") | E36: =IFERROR(IF(AM36+(AM36*$AL$11)=0,"",AM36+(AM36*$AL$11)),"") | F36: =IFERROR(IF(AN36+(AN36*$AL$11)=0,"",AN36+(AN36*$AL$11)),"") | G36: =IFERROR(IF(AO36+(AO36*$AL$11)=0,"",AO36+(AO36*$AL$11)),"") | H36: =IFERROR(IF(AP36+(AP36*$AL$11)=0,"",AP36+(AP36*$AL$11)),"") | I36: =IFERROR(IF(AQ36+(AQ36*$AL$11)=0,"",AQ36+(AQ36*$AL$11)),"") | J36: =IFERROR(IF(AR36+(AR36*$AL$11)=0,"",AR36+(AR36*$AL$11)),"") | ... L36: =IFERROR(IF(AT36+(AT36*$AL$11)=0,"",AT36+(AT36*$AL$11)),"") | N36: =IFERROR(IF(AV36+(AV36*$AL$11)=0,"",AV36+(AV36*$AL$11)),"") | O36: =IFERROR(IF(AW36+(AW36*$AL$11)=0,"",AW36+(AW36*$AL$11)),"") | Q36: 600 | R36: 31.28 | S36: 62.12 | W36: WATER set | AJ36: 600 | AK36: 153.0368 | AL36: 172.1104 | AM36: 187.0064 | AN36: 210.224 | AO36: 239.1872 | AP36: 272.104
B37: 500/750 | C37: =IFERROR(IF(AK37+(AK37*$AL$11)=0,"",AK37+(AK37*$AL$11)),"") | D37: =IFERROR(IF(AL37+(AL37*$AL$11)=0,"",AL37+(AL37*$AL$11)),"") | E37: =IFERROR(IF(AM37+(AM37*$AL$11)=0,"",AM37+(AM37*$AL$11)),"") | F37: =IFERROR(IF(AN37+(AN37*$AL$11)=0,"",AN37+(AN37*$AL$11)),"") | G37: =IFERROR(IF(AO37+(AO37*$AL$11)=0,"",AO37+(AO37*$AL$11)),"") | H37: =IFERROR(IF(AP37+(AP37*$AL$11)=0,"",AP37+(AP37*$AL$11)),"") | I37: =IFERROR(IF(AQ37+(AQ37*$AL$11)=0,"",AQ37+(AQ37*$AL$11)),"") | J37: =IFERROR(IF(AR37+(AR37*$AL$11)=0,"",AR37+(AR37*$AL$11)),"") | ... L37: =IFERROR(IF(AT37+(AT37*$AL$11)=0,"",AT37+(AT37*$AL$11)),"") | N37: =IFERROR(IF(AV37+(AV37*$AL$11)=0,"",AV37+(AV37*$AL$11)),"") | O37: =IFERROR(IF(AW37+(AW37*$AL$11)=0,"",AW37+(AW37*$AL$11)),"") | Q37: 500/750 | R37: 32.33 | S37: 63.27 | W37: Mulit + kous | X37: 45 | AJ37: 500/750 | AM37: 192.0352 | AN37: 216.0928 | AO37: 245.9072 | AP37: 279.3616 | AQ37: 305.1664
B38: 631 | C38: =IFERROR(IF(AK38+(AK38*$AL$11)=0,"",AK38+(AK38*$AL$11)),"") | D38: =IFERROR(IF(AL38+(AL38*$AL$11)=0,"",AL38+(AL38*$AL$11)),"") | E38: =IFERROR(IF(AM38+(AM38*$AL$11)=0,"",AM38+(AM38*$AL$11)),"") | F38: =IFERROR(IF(AN38+(AN38*$AL$11)=0,"",AN38+(AN38*$AL$11)),"") | G38: =IFERROR(IF(AO38+(AO38*$AL$11)=0,"",AO38+(AO38*$AL$11)),"") | H38: =IFERROR(IF(AP38+(AP38*$AL$11)=0,"",AP38+(AP38*$AL$11)),"") | I38: =IFERROR(IF(AQ38+(AQ38*$AL$11)=0,"",AQ38+(AQ38*$AL$11)),"") | J38: =IFERROR(IF(AR38+(AR38*$AL$11)=0,"",AR38+(AR38*$AL$11)),"") | ... O38: =IFERROR(IF(AW38+(AW38*$AL$11)=0,"",AW38+(AW38*$AL$11)),"") | Q38: 631 | R38: 32.33 | S38: 63.27 | W38: Voorwagen | X38: 25.3 | AJ38: 631 | AM38: 192.0352 | AN38: 216.0928 | AO38: 245.9072 | AP38: 279.3616 | AQ38: 305.1664
B39: 650 | C39: =IFERROR(IF(AK39+(AK39*$AL$11)=0,"",AK39+(AK39*$AL$11)),"") | D39: =IFERROR(IF(AL39+(AL39*$AL$11)=0,"",AL39+(AL39*$AL$11)),"") | E39: =IFERROR(IF(AM39+(AM39*$AL$11)=0,"",AM39+(AM39*$AL$11)),"") | F39: =IFERROR(IF(AN39+(AN39*$AL$11)=0,"",AN39+(AN39*$AL$11)),"") | G39: =IFERROR(IF(AO39+(AO39*$AL$11)=0,"",AO39+(AO39*$AL$11)),"") | H39: =IFERROR(IF(AP39+(AP39*$AL$11)=0,"",AP39+(AP39*$AL$11)),"") | I39: =IFERROR(IF(AQ39+(AQ39*$AL$11)=0,"",AQ39+(AQ39*$AL$11)),"") | J39: =IFERROR(IF(AR39+(AR39*$AL$11)=0,"",AR39+(AR39*$AL$11)),"") | ... O39: =IFERROR(IF(AW39+(AW39*$AL$11)=0,"",AW39+(AW39*$AL$11)),"") | Q39: 650 | R39: 33.3 | S39: 64.41 | AJ39: 650 | AK39: 163.0272 | AL39: 182.28 | AM39: 197.8256 | AN39: 222.6 | AO39: 253.3104 | AP39: 287.784 | AQ39: 314.3504
B40: 700 | C40: =IFERROR(IF(AK40+(AK40*$AL$11)=0,"",AK40+(AK40*$AL$11)),"") | D40: =IFERROR(IF(AL40+(AL40*$AL$11)=0,"",AL40+(AL40*$AL$11)),"") | E40: =IFERROR(IF(AM40+(AM40*$AL$11)=0,"",AM40+(AM40*$AL$11)),"") | F40: =IFERROR(IF(AN40+(AN40*$AL$11)=0,"",AN40+(AN40*$AL$11)),"") | G40: =IFERROR(IF(AO40+(AO40*$AL$11)=0,"",AO40+(AO40*$AL$11)),"") | H40: =IFERROR(IF(AP40+(AP40*$AL$11)=0,"",AP40+(AP40*$AL$11)),"") | I40: =IFERROR(IF(AQ40+(AQ40*$AL$11)=0,"",AQ40+(AQ40*$AL$11)),"") | J40: =IFERROR(IF(AR40+(AR40*$AL$11)=0,"",AR40+(AR40*$AL$11)),"") | ... O40: =IFERROR(IF(AW40+(AW40*$AL$11)=0,"",AW40+(AW40*$AL$11)),"") | Q40: 700 | R40: 35.48 | S40: 66.26 | W40: Hanger | X40: 24 | AJ40: 700 | AL40: 195.2496 | AM40: 211.7024 | AN40: 238.4256 | AO40: 271.3648 | AP40: 307.8992 | AQ40: 337.2656
...

Sheet Tarieven 2026
A1: ALGEMENE VERKOOPTARIEVEN 2026 — GMB Leidingtechnieken B.V.
A2: INTERN GEBRUIK — niet delen. De tarieven waarmee we rekenen. Geel = bewerkbaar.
D3: Hoog tarief | F3: Laag tarief
A4: Materieelstuk | B4: Bijzonderheden | C4: Bediening | D4: uur (€) | E4: dag (€) | F4: uur (€) | G4: dag (€) | I4: Tariefbasis: | J4: Laag
A5: RR combinatie | B5: n.v.t. | C5: 2 man | D5: 348.14 | E5: 2785.1 | F5: 301.08 | G5: 2408.62
A6: Hogedrukwagen | B6: n.v.t. | C6: 1 man | D6: 187.68 | E6: 1501.42 | F6: 182.01 | G6: 1456.06
A7: Hogedrukwagen | B7: n.v.t. | C7: 2 man | D7: 256.28 | E7: 2050.27 | F7: 248.91 | G7: 1991.3
A8: Vacuumwagen | B8: n.v.t. | C8: 1 man | D8: 184.28 | E8: 1474.2 | F8: 178.61 | G8: 1428.84
A9: Vacuumwagen | B9: n.v.t. | C9: 2 man | D9: 254.58 | E9: 2036.66 | F9: 243.81 | G9: 1950.48
A10: Combi | B10: n.v.t. | C10: 1 man | D10: 233.6 | E10: 1868.83 | F10: 217.73 | G10: 1741.82
A11: Combi | B11: n.v.t. | C11: 2 man | D11: 302.21 | E11: 2417.69 | F11: 282.93 | G11: 2263.46
A12: Inspectie-unit conventioneel | B12: n.v.t. | C12: 1 man | D12: 221.13 | E12: 1769.04 | F12: 208.66 | G12: 1669.25
A13: Inspectie-unit conventioneel | B13: n.v.t. | C13: 2 man | D13: 292.57 | E13: 2340.58 | F13: 260.25 | G13: 2082.02
A14: Inspectie-unit Pano | B14: n.v.t. | C14: 1 man | D14: 284.07 | E14: 2272.54 | F14: 257.99 | G14: 2063.88
A15: Inspectie-unit Pano | B15: n.v.t. | C15: 2 man | D15: 352.67 | E15: 2821.39 | F15: 323.19 | G15: 2585.52
A16: Robotfrees-unit | B16: n.v.t. | C16: 2 man | D16: 299.94 | E16: 2399.54 | F16: 261.95 | G16: 2095.63
... A18: Fourtrack honda | B18: n.v.t. | C18: n.v.t. | D18: 57.83 | E18: 462.67 | F18: 57.83 | G18: 462.67
A19: Safety-unit | B19: per dag | C19: n.v.t. | D19: n.v.t. | E19: n.v.t. | F19: n.v.t. | G19: n.v.t.
A20: Borden-wagen | B20: per dag | C20: n.v.t. | D20: n.v.t. | E20: n.v.t. | F20: n.v.t. | G20: n.v.t.
A21: Transportbus | B21: n.v.t. | C21: n.v.t. | D21: 27.78 | E21: 222.26 | F21: 27.78 | G21: 222.26
A22: Stortkosten RKG-slib (per ton) | B22: per ton | C22: n.v.t. | D22: 98.5 | E22: n.v.t. | F22: 98.5 | G22: n.v.t.
A23: Opstellen werkvergunning | B23: per werk | C23: n.v.t. | D23: n.v.t. | E23: n.v.t. | F23: n.v.t. | G23: n.v.t.
A24: Werkvergunning per persoon | B24: per dag | C24: n.v.t. | D24: n.v.t. | E24: n.v.t. | F24: n.v.t. | G24: n.v.t.
A25: Manuren rapporteur | B25: n.v.t. | C25: n.v.t. | D25: 86 | E25: 688 | F25: 86 | G25: 688
A26: Manuren operationeel personeel | B26: n.v.t. | C26: n.v.t. | D26: 75 | E26: 600 | F26: 75 | G26: 600
A27: PLOEGEN & OVERIG (dagprijs)
A28: Viltploeg water chip | C28: 4 man | G28: 6510
A29: Viltploeg water steiger | C29: 6 man | G29: 7980
A30: Inzet koolbak | G30: 262.5
A31: Dikmans extra incl. man | G31: 2100
A32: Viltploeg stoom drukvat | C32: 4 man | G32: 6510
A33: Viltploeg stoom DGA | C33: 6 man | G33: 7980
A34: UV-ploeg | C34: 4 man | G34: 6300
A35: PERSONEEL (uur / dag)
A36: Werkvoorbereider | F36: 89.25 | G36: 714
A37: Uitvoerder | F37: 89.25 | G37: 714
A38: Projectleider | F38: 115.5 | G38: 924
A39: Calculator | F39: 89.25 | G39: 714
A41: VOORWAARDEN
A42: • Een dag bestaat uit 8 werkuren tussen 07.30 en 16.30 uur. Het dagtarief is 8× het uurtarief.
...

Sheet Instellingen
A1: INSTELLINGEN — Insituform detailcalculatie
A3: Parameter | B3: Waarde | C3: Toelichting
A4: Indexatie % op impregnatieprijs | B4: 0 | C4: Extra index bovenop de Insituform-lijstprijs (los van Prijzen-blad).
A5: Extra meters droge kous t.o.v. omslaan | B5: 1 | C5: Droge kous (m) = Omslaan (m) + deze waarde.
A6: Standaard omslaan (m) indien leeg | B6: 4.5 | C6: Gebruikt als kolom 'Omslaan' leeg is.
A7: Standaard aantal eindstuk | B7: 1
A8: Standaard aantal omslaan | B8: 1

Sheet Impregnatie
A1: IMPREGNATIE — prijs per meter (€/m)
A3: DN \ Dikte (mm) | B3: 4.5 | C3: 6 | D3: 7.5 | E3: 9 | F3: 10.5 | G3: 12 | H3: 13.5 | I3: 15 | J3: 16.5 | K3: 18 | L3: 19.5 | M3: 21 | N3: 22.5 | O3: 24
A4: 200 | B4: 31.65 | C4: 36.91 | D4: 40.98
A5: 250 | C5: 42.44 | D5: 47.54 | E5: 51.91
A6: 300 | C6: 48.04 | D6: 54.1 | E6: 59.33 | F6: 66.54
A7: 350 | C7: 53.57 | D7: 60.73 | E7: 66.92 | F7: 76.15 | G7: 81.4
A8: 400 | D8: 66.65 | E8: 74 | F8: 84.26 | G8: 90.46
A9: 450 | D9: 73.34 | E9: 81.7 | F9: 92.88 | G9: 99.93 | H9: 108.89
A10: 500 | E10: 89.61 | F10: 101.96 | G10: 109.89 | H10: 119.95 | I10: 128.83
A11: 550 | E11: 97.46 | F11: 110.77 | G11: 119.87 | H11: 130.98 | I11: 140.72
A12: 600 | E12: 103.87 | F12: 117.99 | G12: 128 | H12: 139.87 | I12: 150.76
A13: 650 | F13: 126.88 | G13: 137.56 | H13: 150.53 | I13: 162.11 | J13: 178.08
A14: 700 | F14: 135.77 | G14: 146.72 | H14: 160.79 | I14: 173.3 | J14: 190.45
A15: 750 | G15: 156.31 | H15: 171.45 | I15: 184.81 | J15: 203.06 | K15: 216.57
A16: 800 | G16: 165.94 | H16: 183.29 | I16: 197.99 | J16: 217.33 | K16: 230.35
A17: 850 | H17: 193.75 | I17: 208.47 | J17: 229.23 | K17: 242.68 | L17: 261.37
A18: 900 | H18: 202.53 | I18: 218.95 | J18: 240.23 | K18: 254.97 | L18: 274.74
A19: 950 | I19: 229.42 | J19: 252.76 | K19: 268.53 | L19: 289.53 | M19: 308.87
A20: 1000 | I20: 245.06 | J20: 268.39 | K20: 285.39 | L20: 307.66 | M20: 324.51
A21: 1050 | J21: 281.94 | K21: 299.17 | L21: 321.65 | M21: 340.65 | N21: 365.87
A22: 1100 | J22: 295.81 | K22: 312.91 | L22: 336.96 | M22: 356.41 | N22: 380.42
A23: 1150 | K23: 326.66 | L23: 352.27 | M23: 372.17 | N23: 394.97 | O23: 417.74
A24: 1200 | K24: 340.28 | L24: 367.17 | M24: 386.18 | N24: 410.52 | O24: 434.81
A25: 1250 | K25: 354.05 | L25: 381.98 | M25: 401.82 | N25: 427.24 | O25: 452.57

Sheet Droge kous
A1: DROGE KOUS — prijs per meter (€/m)
A3: DN \ Dikte (mm) | B3: 3 | C3: 4.5 | D3: 6 | E3: 7.5 | F3: 9 | G3: 10.5 | H3: 12 | I3: 13.5 | J3: 15 | K3: 16.5 | L3: 18 | M3: 19.5 | N3: 21 | O3: 22.5 | P3: 24 | Q3: 25.5 | R3: 27 | S3: 28.5 | T3: 30
A4: 100 | B4: 3.79 | C4: 4.39 | D4: 4.71
A5: 150 | B5: 4.81 | C5: 5.71 | D5: 6.02
A6: 200 | B6: 6.15 | C6: 7.2 | D6: 7.38 | E6: 8.18
A7: 225 | B7: 6.92 | C7: 8.13 | D7: 8.24 | E7: 9.22
A8: 250 | B8: 7.69 | C8: 8.94 | D8: 9.05 | E8: 10.03 | F8: 10.54
A9: 300 | B9: 9.22 | C9: 10.73 | D9: 10.77 | E9: 11.88 | F9: 12.45 | G9: 14.41 | H9: 14.93
A10: 350 | B10: 10.76 | C10: 12.53 | D10: 12.45 | E10: 13.78 | F10: 14.47 | G10: 17.3 | H10: 17.41
A11: 400 | B11: 12.08 | C11: 13.65 | D11: 13.77 | E11: 15.18 | F11: 16.14 | G11: 19.15 | H11: 19.37 | I11: 20.84 | J11: 21.86
A12: 450 | D12: 15.35 | E12: 17.12 | F12: 18.24 | G12: 21.34 | H12: 21.62 | I12: 23.24 | J12: 24.36
A13: 500 | D13: 17.06 | E13: 19.49 | F13: 20.49 | G13: 23.86 | H13: 24.2 | I13: 26.05 | J13: 27.12 | K13: 30.43 | L13: 30.99
A14: 550
A15: 600
A16: 650
A17: 700
A18: 750
A19: 800
A20: 850
A21: 900
A22: 950
A23: 1000
A24: 1050
A25: 1100
... A33: 1500

Sheet Sundry
A1: SUNDRY — toebehoren (€)
A3: DN ondergrens | B3: Bereik | C3: Verloop | D3: Eindstuk | E3: Omslaan | F3: Korte lengte | G3: Min. order (m)
A4: 0 | B4: 0 - 250 | C4: 235.72 | D4: 160.98 | E4: 160.98 | F4: 0 | G4: 0
A5: 251 | B5: 251 - 300 | C5: 252.96 | D5: 160.98 | E5: 160.98 | F5: 0 | G5: 0
A6: 301 | B6: 301 - 350 | C6: 264.46 | D6: 160.98 | E6: 160.98 | F6: 0 | G6: 0
A7: 351 | B7: 351 - 400 | C7: 264.46 | D7: 166.73 | E7: 166.73 | F7: 0 | G7: 0
A8: 401 | B8: 401 - 450 | C8: 298.96 | D8: 189.72 | E8: 189.72 | F8: 0 | G8: 0
A9: 451 | B9: 451 - 550 | C9: 327.7 | D9: 195.47 | E9: 195.47 | F9: 0 | G9: 0
A10: 551 | B10: 551 - 650 | C10: 344.95 | D10: 252.96 | E10: 252.96 | F10: 574.92 | G10: 80
A11: 651 | B11: 651 - 750 | C11: 379.45 | D11: 321.96 | E11: 321.96 | F11: 574.92 | G11: 50
A12: 751 | B12: 751 - 850 | C12: 402.44 | D12: 385.2 | E12: 385.2 | F12: 574.92 | G12: 50
A13: 851 | B13: 851 - 900 | C13: 459.94 | D13: 431.19 | E13: 431.19 | F13: 574.92 | G13: 50
A14: 901 | B14: 901 - 950 | C14: 517.43 | D14: 459.94 | E14: 459.94 | F14: 574.92 | G14: 50
A15: 951 | B15: 951 - 1100 | C15: 574.92 | D15: 488.68 | E15: 488.68 | F15: 574.92 | G15: 50
... A20: 1601 | B20: 1601 + | C20: 1494.79 | D20: 1149.84 | E20: 1149.84 | F20: 574.92 | G20: 25

Sheet Insituform-calc
A1: INSITUFORM DETAILCALCULATIE — impregnatie + droge kous + sundry per kous
A2: Basis (oranje) verplicht: DN, dikte, lengte geimpr. — Detail (geel) optioneel. Grijs = automatisch. Sluit aan op de 'Materiaal'-regels in Calculatie.
